Workbook

Sheet Hướng dẫn
B1: HƯỚNG DẪN SỬ DỤNG
B2: CÁCH SỬ DỤNG FILE EVM REPORT
B3: No. | C3: Bước | D3: Mô tả
B4: 1 | C4: Bước 1: Nhập "Hạng mục công việc" | D4: Vào sheet "PV (Kế hoạch)", nhập hạng mục công việc vào cột "Hạng mục công việc". Nếu thiếu dòng thì chèn thêm dòng vào phía trên của dòng cuối cùng (dòng bôi xám) của cả 4 sheets "PV (Kế hoạch)", "EV (Tiến độ lũy kế)", "SPI", "EV (Hoàn thành thực tế)" và copy paste công thức của 1 dòng đã có vào các dòng mới. Chú ý chèn số lượng dòng và vị trí chèn dòng giống nhau cho cả 4 sheets.
B5: 2 | C5: Bước 2: Nhập PV (Planned Value) | D5: Vào sheet "PV (Kế hoạch)", nhập công số (man-day) kế hoạch/cho từng hạng mục/theo từng tuần (không lũy kế).
B6: 3 | C6: Bước 3: Nhập EV (Earned Value) | D6: Vào sheet "EV (Tiến độ lũy kế)", nhập Tiến độ thực tế lũy kế đến tuần tương ứng. Công số thực tế (man-day) đã hoàn thành/cho từng hạng mục/theo từng tuần trong sheet "EV (Hoàn thành thực tế)" sẽ được tính tự động.
B7: 4 | C7: Bước 4: Nhập AC (Actual Cost) | D7: Vào sheet "AC (Chi phí)" và nhập chi phí thực tế (man-day) đã chi cho từng hạng mục theo từng tuần
B8: 5 | C8: Bước 5: Xem CPI | D8: Sheet "CPI" tự động tính Cost Performance Index. Xanh = Tốt (CPI > 1), Vàng = Xấu (0.85 <= CPI < 1), Đỏ = Rất xấu (CPI < 0.85)
B9: 6 | C9: Bước 6: Xem SPI | D9: Sheet "SPI" tự động tính Schedule Performance Index. Xanh = Tốt (SPI > 1), Vàng = Xấu (0.85 <= SPI < 1), Đỏ = Rất xấu (SPI < 0.85)
B11: ĐỊNH NGHĨA CÁC CHỈ SỐ
B12: No. | C12: Chỉ số | D12: Định nghĩa | E12: Công thức
B13: 1 | C13: PV | D13: Planned Value - Giá trị công việc kế hoạch | E13: Công số dự kiến theo kế hoạch
B14: 2 | C14: EV | D14: Earned Value - Giá trị công việc đạt được | E14: Công số thực tế đã hoàn thành
B15: 3 | C15: AC | D15: Actual Cost - Chi phí thực tế | E15: Công số thực tế đã chi
B16: 4 | C16: CPI | D16: Cost Performance Index - Chỉ số hiệu suất chi phí | E16: EV / AC
B17: 5 | C17: SPI | D17: Schedule Performance Index - Chỉ số hiệu suất tiến độ | E17: EV / PV
B18: 6 | C18: CV | D18: Cost Variance - Chênh lệch chi phí | E18: EV - AC
B19: 7 | C19: SV | D19: Schedule Variance - Chênh lệch tiến độ | E19: EV - PV
B21: QUY TẮC HIỂN THỊ MÀU
B22: No. | C22: Điều kiện | D22: Màu hiển thị | E22: Ý nghĩa | F22: Giá trị 1 | G22: Giá trị 2
B23: 1 | C23: CPI > 1 hoặc SPI > 1 | D23: Xanh lá cây | E23: ✅ Tốt | F23: 1
B24: 2 | C24: CPI = 1 hoặc SPI = 1 | D24: Trắng | E24: ⚪ Bình thường | F24: 1
B25: 3 | C25: 0.85 <= CPI < 1 hoặc 0.85 <= SPI < 1 | D25: Vàng | E25: ❌ Xấu | F25: 0.85 | G25: 1
B26: 4 | C26: CPI < 0.85 hoặc SPI < 0.85 | D26: Đỏ | E26: ❌ Rất xấu | F26: 0.85
B28: ĐỐI TƯỢNG DỰ ÁN ÁP DỤNG
B29: Các dự án lớn (revenue >= 200 JPY man), và làm production

Sheet PV (Kế hoạch)
B1: PV - PLANNED VALUE (CÔNG SỐ KẾ HOẠCH TỪNG TUẦN) (md)
B2: No. | C2: Hạng mục công việc | D2: Tuần 1 2/3/26 | E2: Tuần 2 | F2: Tuần 3 | G2: Tuần 4 | H2: Tuần 5 | I2: Tuần 6 | J2: Tuần 7 | K2: Tuần 8 | L2: Tuần 9 | M2: Tuần 10 | N2: Tuần 11 | O2: Tuần 12 | P2: Tuần 13 | Q2: Tuần 14 | R2: Tuần 15 | S2: Tuần 16 | T2: Tuần 17 | U2: Tuần 18 | V2: Tuần 19 | W2: Tuần 20 | X2: Tuần 21 | Y2: Tuần 22 | Z2: Tuần 23 | AA2: Tuần 24 | AB2: Tổng
B3: =ROW()-2 -> 1 | C3: Phân tích yêu cầu (Requirements Analysis) | D3: 5 | E3: 5 | F3: 3 | AB3: =SUM(D3:AA3) -> 13
B4: =ROW()-2 -> 2 | C4: Thiết kế hệ thống (System Design) | F4: 3 | G4: 5 | H4: 5 | I4: 2 | AB4: =SUM(D4:AA4) -> 15
B5: =ROW()-2 -> 3 | C5: Thiết kế database (Database Design) | G5: 2 | H5: 3 | I5: 3 | AB5: =SUM(D5:AA5) -> 8
B6: =ROW()-2 -> 4 | C6: Thiết kế UI/UX | G6: 2 | H6: 3 | I6: 3 | J6: 2 | AB6: =SUM(D6:AA6) -> 10
B7: =ROW()-2 -> 5 | C7: Phát triển Backend - Module User | I7: 2 | J7: 5 | K7: 5 | L7: 5 | M7: 3 | AB7: =SUM(D7:AA7) -> 20
B8: =ROW()-2 -> 6 | C8: Phát triển Backend - Module Order | K8: 2 | L8: 5 | M8: 5 | N8: 5 | O8: 3 | AB8: =SUM(D8:AA8) -> 20
B9: =ROW()-2 -> 7 | C9: Phát triển Backend - Module Payment | M9: 2 | N9: 5 | O9: 5 | P9: 5 | AB9: =SUM(D9:AA9) -> 17
B10: =ROW()-2 -> 8 | C10: Phát triển Backend - Module Report | O10: 2 | P10: 5 | Q10: 5 | R10: 3 | AB10: =SUM(D10:AA10) -> 15
B11: =ROW()-2 -> 9 | C11: Phát triển Frontend - Trang chủ | J11: 2 | K11: 3 | L11: 3 | AB11: =SUM(D11:AA11) -> 8
B12: =ROW()-2 -> 10 | C12: Phát triển Frontend - Module User | L12: 2 | M12: 5 | N12: 5 | O12: 3 | AB12: =SUM(D12:AA12) -> 15
B13: =ROW()-2 -> 11 | C13: Phát triển Frontend - Module Order | N13: 2 | O13: 5 | P13: 5 | Q13: 3 | AB13: =SUM(D13:AA13) -> 15
B14: =ROW()-2 -> 12 | C14: Phát triển Frontend - Module Payment | P14: 2 | Q14: 5 | R14: 5 | AB14: =SUM(D14:AA14) -> 12
B15: =ROW()-2 -> 13 | C15: Phát triển Frontend - Module Report | R15: 2 | S15: 5 | T15: 3 | AB15: =SUM(D15:AA15) -> 10
B16: =ROW()-2 -> 14 | C16: Tích hợp API bên thứ 3 | Q16: 2 | R16: 3 | S16: 3 | AB16: =SUM(D16:AA16) -> 8
B17: =ROW()-2 -> 15 | C17: Unit Testing | M17: 1 | N17: 1 | O17: 1 | P17: 1 | Q17: 2 | R17: 2 | S17: 2 | T17: 2 | AB17: =SUM(D17:AA17) -> 12
B18: =ROW()-2 -> 16 | C18: Integration Testing | S18: 2 | T18: 3 | U18: 3 | AB18: =SUM(D18:AA18) -> 8
B19: =ROW()-2 -> 17 | C19: System Testing | U19: 2 | V19: 5 | W19: 5 | AB19: =SUM(D19:AA19) -> 12
B20: =ROW()-2 -> 18 | C20: UAT (User Acceptance Testing) | W20: 2 | X20: 5 | Y20: 3 | AB20: =SUM(D20:AA20) -> 10
B21: =ROW()-2 -> 19 | C21: Bug fixing | V21: 2 | W21: 3 | X21: 3 | Y21: 2 | AB21: =SUM(D21:AA21) -> 10
B22: =ROW()-2 -> 20 | C22: Performance Optimization | X22: 2 | Y22: 3 | AB22: =SUM(D22:AA22) -> 5
B23: =ROW()-2 -> 21 | C23: Security Review | Y23: 2 | Z23: 2 | AB23: =SUM(D23:AA23) -> 4
B24: =ROW()-2 -> 22 | C24: Documentation | U24: 1 | V24: 1 | W24: 1 | X24: 1 | Y24: 2 | Z24: 2 | AB24: =SUM(D24:AA24) -> 8
B25: =ROW()-2 -> 23 | C25: Training | Z25: 3 | AA25: 2 | AB25: =SUM(D25:AA25) -> 5
B26: =ROW()-2 -> 24 | C26: Deployment | Z26: 2 | AA26: 3 | AB26: =SUM(D26:AA26) -> 5
B27: =ROW()-2 -> 25 | C27: Go-live Support | AA27: 5 | AB27: =SUM(D27:AA27) -> 5
B28: =ROW()-2 -> 26 | AB28: =SUM(D28:AA28) -> 0
B29: =ROW()-2 -> 27 | AB29: =SUM(D29:AA29) -> 0
B30: =ROW()-2 -> 28 | AB30: =SUM(D30:AA30) -> 0
B31: =ROW()-2 -> 29 | AB31: =SUM(D31:AA31) -> 0
C32: Không chèn thêm dòng vào dưới dòng này | AB32: =SUM(D32:AA32) -> 0
C33: TỔNG CỘNG TỪNG TUẦN | D33: =SUM(D3:D32) -> 5 | E33: =SUM(E3:E32) -> 5 | F33: =SUM(F3:F32) -> 6 | G33: =SUM(G3:G32) -> 9 | H33: =SUM(H3:H32) -> 11 | I33: =SUM(I3:I32) -> 10 | J33: =SUM(J3:J32) -> 9 | K33: =SUM(K3:K32) -> 10 | ... AB33: =SUM(AB3:AB32) -> 270
C34: TỔNG CỘNG LŨY KẾ | D34: =D33 -> 5 | E34: =D34+E33 -> 10 | F34: =E34+F33 -> 16 | G34: =F34+G33 -> 25 | H34: =G34+H33 -> 36 | I34: =H34+I33 -> 46 | J34: =I34+J33 -> 55 | K34: =J34+K33 -> 65 | L34: =K34+L33 -> 80 | ... AA34: =Z34+AA33 -> 270

Sheet EV (Tiến độ lũy kế)
B1: EV - EARNED VALUE (TIẾN ĐỘ HOÀN THÀNH THỰC TẾ LŨY KẾ) (md)
B2: No. | C2: Hạng mục công việc | D2: Tuần 1 | E2: Tuần 2 | F2: Tuần 3 | G2: Tuần 4 | H2: Tuần 5 | I2: Tuần 6 | J2: Tuần 7 | K2: Tuần 8 | L2: Tuần 9 | M2: Tuần 10 | N2: Tuần 11 | O2: Tuần 12 | P2: Tuần 13 | Q2: Tuần 14 | R2: Tuần 15 | S2: Tuần 16 | T2: Tuần 17 | U2: Tuần 18 | V2: Tuần 19 | W2: Tuần 20 | X2: Tuần 21 | Y2: Tuần 22 | Z2: Tuần 23 | AA2: Tuần 24
B3: =IF('PV (Kế hoạch)'!B3="","",'PV (Kế hoạch)'!B3) -> 1 | C3: =IF('PV (Kế hoạch)'!C3="","",'PV (Kế hoạch)'!C3) -> Phân tích yêu cầu (Requirements Analysis) | D3: 0.38 | E3: 0.77 | F3: 1 | G3: 1 | H3: 1 | I3: 1 | J3: 1 | K3: 1 | L3: 1 | M3: 1 | N3: 1 | O3: 1 | P3: 1 | Q3: 1 | R3: 1 | S3: 1 | T3: 1 | U3: 1 | V3: =U3 -> 1 | W3: =V3 -> 1 | X3: =W3 -> 1 | Y3: =X3 -> 1 | Z3: =Y3 -> 1 | AA3: =Z3 -> 1
B4: =IF('PV (Kế hoạch)'!B4="","",'PV (Kế hoạch)'!B4) -> 2 | C4: =IF('PV (Kế hoạch)'!C4="","",'PV (Kế hoạch)'!C4) -> Thiết kế hệ thống (System Design) | D4: 0 | E4: 0 | F4: 0.2 | G4: 0.53 | H4: 0.87 | I4: 1 | J4: 1 | K4: 1 | L4: 1 | M4: 1 | N4: 1 | O4: 1 | P4: 1 | Q4: 1 | R4: 1 | S4: 1 | T4: 1 | U4: 1 | V4: =U4 -> 1 | W4: =V4 -> 1 | X4: =W4 -> 1 | Y4: =X4 -> 1 | Z4: =Y4 -> 1 | AA4: =Z4 -> 1
B5: =IF('PV (Kế hoạch)'!B5="","",'PV (Kế hoạch)'!B5) -> 3 | C5: =IF('PV (Kế hoạch)'!C5="","",'PV (Kế hoạch)'!C5) -> Thiết kế database (Database Design) | D5: 0 | E5: 0 | F5: 0 | G5: 0.25 | H5: 0.63 | I5: 1 | J5: 1 | K5: 1 | L5: 1 | M5: 1 | N5: 1 | O5: 1 | P5: 1 | Q5: 1 | R5: 1 | S5: 1 | T5: 1 | U5: 1 | V5: =U5 -> 1 | W5: =V5 -> 1 | X5: =W5 -> 1 | Y5: =X5 -> 1 | Z5: =Y5 -> 1 | AA5: =Z5 -> 1
B6: =IF('PV (Kế hoạch)'!B6="","",'PV (Kế hoạch)'!B6) -> 4 | C6: =IF('PV (Kế hoạch)'!C6="","",'PV (Kế hoạch)'!C6) -> Thiết kế UI/UX | D6: 0 | E6: 0 | F6: 0 | G6: 0.2 | H6: 0.5 | I6: 0.8 | J6: 1 | K6: 1 | L6: 1 | M6: 1 | N6: 1 | O6: 1 | P6: 1 | Q6: 1 | R6: 1 | S6: 1 | T6: 1 | U6: 1 | V6: =U6 -> 1 | W6: =V6 -> 1 | X6: =W6 -> 1 | Y6: =X6 -> 1 | Z6: =Y6 -> 1 | AA6: =Z6 -> 1
B7: =IF('PV (Kế hoạch)'!B7="","",'PV (Kế hoạch)'!B7) -> 5 | C7: =IF('PV (Kế hoạch)'!C7="","",'PV (Kế hoạch)'!C7) -> Phát triển Backend - Module User | D7: 0 | E7: 0 | F7: 0 | G7: 0 | H7: 0 | I7: 0.1 | J7: 0.35 | K7: 0.6 | L7: 0.85 | M7: 1 | N7: 1 | O7: 1 | P7: 1 | Q7: 1 | R7: 1 | S7: 1 | T7: 1 | U7: 1 | V7: =U7 -> 1 | W7: =V7 -> 1 | X7: =W7 -> 1 | Y7: =X7 -> 1 | Z7: =Y7 -> 1 | AA7: =Z7 -> 1
B8: =IF('PV (Kế hoạch)'!B8="","",'PV (Kế hoạch)'!B8) -> 6 | C8: =IF('PV (Kế hoạch)'!C8="","",'PV (Kế hoạch)'!C8) -> Phát triển Backend - Module Order | D8: 0 | E8: 0 | F8: 0 | G8: 0 | H8: 0 | I8: 0 | J8: 0 | K8: 0.1 | L8: 0.35 | M8: 0.6 | N8: 0.85 | O8: 1 | P8: 1 | Q8: 1 | R8: 1 | S8: 1 | T8: 1 | U8: 1 | V8: =U8 -> 1 | W8: =V8 -> 1 | X8: =W8 -> 1 | Y8: =X8 -> 1 | Z8: =Y8 -> 1 | AA8: =Z8 -> 1
B9: =IF('PV (Kế hoạch)'!B9="","",'PV (Kế hoạch)'!B9) -> 7 | C9: =IF('PV (Kế hoạch)'!C9="","",'PV (Kế hoạch)'!C9) -> Phát triển Backend - Module Payment | D9: 0 | E9: 0 | F9: 0 | G9: 0 | H9: 0 | I9: 0 | J9: 0 | K9: 0 | L9: 0 | M9: 0.12 | N9: 0.41 | O9: 0.71 | P9: 1 | Q9: 1 | R9: 1 | S9: 1 | T9: 1 | U9: 1 | V9: =U9 -> 1 | W9: =V9 -> 1 | X9: =W9 -> 1 | Y9: =X9 -> 1 | Z9: =Y9 -> 1 | AA9: =Z9 -> 1
B10: =IF('PV (Kế hoạch)'!B10="","",'PV (Kế hoạch)'!B10) -> 8 | C10: =IF('PV (Kế hoạch)'!C10="","",'PV (Kế hoạch)'!C10) -> Phát triển Backend - Module Report | D10: 0 | E10: 0 | F10: 0 | G10: 0 | H10: 0 | I10: 0 | J10: 0 | K10: 0 | L10: 0 | M10: 0 | N10: 0 | O10: 0.13 | P10: 0.47 | Q10: 0.8 | R10: 1 | S10: 1 | T10: 1 | U10: 1 | V10: =U10 -> 1 | W10: =V10 -> 1 | X10: =W10 -> 1 | Y10: =X10 -> 1 | Z10: =Y10 -> 1 | AA10: =Z10 -> 1
B11: =IF('PV (Kế hoạch)'!B11="","",'PV (Kế hoạch)'!B11) -> 9 | C11: =IF('PV (Kế hoạch)'!C11="","",'PV (Kế hoạch)'!C11) -> Phát triển Frontend - Trang chủ | D11: 0 | E11: 0 | F11: 0 | G11: 0 | H11: 0 | I11: 0 | J11: 0.25 | K11: 0.63 | L11: 1 | M11: 1 | N11: 1 | O11: 1 | P11: 1 | Q11: 1 | R11: 1 | S11: 1 | T11: 1 | U11: 1 | V11: =U11 -> 1 | W11: =V11 -> 1 | X11: =W11 -> 1 | Y11: =X11 -> 1 | Z11: =Y11 -> 1 | AA11: =Z11 -> 1
B12: =IF('PV (Kế hoạch)'!B12="","",'PV (Kế hoạch)'!B12) -> 10 | C12: =IF('PV (Kế hoạch)'!C12="","",'PV (Kế hoạch)'!C12) -> Phát triển Frontend - Module User | D12: 0 | E12: 0 | F12: 0 | G12: 0 | H12: 0 | I12: 0 | J12: 0 | K12: 0 | L12: 0.13 | M12: 0.47 | N12: 0.8 | O12: 1 | P12: 1 | Q12: 1 | R12: 1 | S12: 1 | T12: 1 | U12: 1 | V12: =U12 -> 1 | W12: =V12 -> 1 | X12: =W12 -> 1 | Y12: =X12 -> 1 | Z12: =Y12 -> 1 | AA12: =Z12 -> 1
B13: =IF('PV (Kế hoạch)'!B13="","",'PV (Kế hoạch)'!B13) -> 11 | C13: =IF('PV (Kế hoạch)'!C13="","",'PV (Kế hoạch)'!C13) -> Phát triển Frontend - Module Order | D13: 0 | E13: 0 | F13: 0 | G13: 0 | H13: 0 | I13: 0 | J13: 0 | K13: 0 | L13: 0 | M13: 0 | N13: 0.13 | O13: 0.47 | P13: 0.8 | Q13: 1 | R13: 1 | S13: 1 | T13: 1 | U13: 1 | V13: =U13 -> 1 | W13: =V13 -> 1 | X13: =W13 -> 1 | Y13: =X13 -> 1 | Z13: =Y13 -> 1 | AA13: =Z13 -> 1
B14: =IF('PV (Kế hoạch)'!B14="","",'PV (Kế hoạch)'!B14) -> 12 | C14: =IF('PV (Kế hoạch)'!C14="","",'PV (Kế hoạch)'!C14) -> Phát triển Frontend - Module Payment | D14: 0 | E14: 0 | F14: 0 | G14: 0 | H14: 0 | I14: 0 | J14: 0 | K14: 0 | L14: 0 | M14: 0 | N14: 0 | O14: 0 | P14: 0.17 | Q14: 0.58 | R14: 1 | S14: 1 | T14: 1 | U14: 1 | V14: =U14 -> 1 | W14: =V14 -> 1 | X14: =W14 -> 1 | Y14: =X14 -> 1 | Z14: =Y14 -> 1 | AA14: =Z14 -> 1
... B27: =IF('PV (Kế hoạch)'!B27="","",'PV (Kế hoạch)'!B27) -> 25 | C27: =IF('PV (Kế hoạch)'!C27="","",'PV (Kế hoạch)'!C27) -> Go-live Support | D27: 0 | E27: 0 | F27: 0 | G27: 0 | H27: 0 | I27: 0 | J27: 0 | K27: 0 | L27: 0 | M27: 0 | N27: 0 | O27: 0 | P27: 0 | Q27: 0 | R27: 0 | S27: 0 | T27: 0 | U27: 0 | V27: =U27 -> 0 | W27: =V27 -> 0 | X27: =W27 -> 0 | Y27: =X27 -> 0 | Z27: =Y27 -> 0 | AA27: =Z27 -> 0
B28: =IF('PV (Kế hoạch)'!B28="","",'PV (Kế hoạch)'!B28) -> 26 | C28: =IF('PV (Kế hoạch)'!C28="","",'PV (Kế hoạch)'!C28)
B29: =IF('PV (Kế hoạch)'!B29="","",'PV (Kế hoạch)'!B29) -> 27 | C29: =IF('PV (Kế hoạch)'!C29="","",'PV (Kế hoạch)'!C29)
B30: =IF('PV (Kế hoạch)'!B30="","",'PV (Kế hoạch)'!B30) -> 28 | C30: =IF('PV (Kế hoạch)'!C30="","",'PV (Kế hoạch)'!C30)
B31: =IF('PV (Kế hoạch)'!B31="","",'PV (Kế hoạch)'!B31) -> 29 | C31: =IF('PV (Kế hoạch)'!C31="","",'PV (Kế hoạch)'!C31)
B32: =IF('PV (Kế hoạch)'!B32="","",'PV (Kế hoạch)'!B32) | C32: =IF('PV (Kế hoạch)'!C32="","",'PV (Kế hoạch)'!C32) -> Không chèn thêm dòng vào dưới dòng này
C34: TIẾN ĐỘ TỔNG CỘNG LŨY KẾ | D34: =ROUND(SUM('EV (Hoàn thành thực tế)'!$D33:D33)/SUM('PV (Kế hoạch)'!$D33:$AA33),2) -> 0.02 | E34: =ROUND(SUM('EV (Hoàn thành thực tế)'!$D33:E33)/SUM('PV (Kế hoạch)'!$D33:$AA33),2) -> 0.04 | F34: =ROUND(SUM('EV (Hoàn thành thực tế)'!$D33:F33)/SUM('PV (Kế hoạch)'!$D33:$AA33),2) -> 0.06 | G34: =ROUND(SUM('EV (Hoàn thành thực tế)'!$D33:G33)/SUM('PV (Kế hoạch)'!$D33:$AA33),2) -> 0.09 | H34: =ROUND(SUM('EV (Hoàn thành thực tế)'!$D33:H33)/SUM('PV (Kế hoạch)'!$D33:$AA33),2) -> 0.13 | I34: =ROUND(SUM('EV (Hoàn thành thực tế)'!$D33:I33)/SUM('PV (Kế hoạch)'!$D33:$AA33),2) -> 0.17 | J34: =ROUND(SUM('EV (Hoàn thành thực tế)'!$D33:J33)/SUM('PV (Kế hoạch)'!$D33:$AA33),2) -> 0.2 | K34: =ROUND(SUM('EV (Hoàn thành thực tế)'!$D33:K33)/SUM('PV (Kế hoạch)'!$D33:$AA33),2) -> 0.24 | ... AA34: =ROUND(SUM('EV (Hoàn thành thực tế)'!$D33:AA33)/SUM('PV (Kế hoạch)'!$D33:$AA33),2) -> 0.77

Sheet SPI
B1: SPI - SCHEDULE PERFORMANCE INDEX (CHỈ SỐ HIỆU SUẤT TIẾN ĐỘ)
B2: No. | C2: Hạng mục công việc | D2: Tuần 1 | E2: Tuần 2 | F2: Tuần 3 | G2: Tuần 4 | H2: Tuần 5 | I2: Tuần 6 | J2: Tuần 7 | K2: Tuần 8 | L2: Tuần 9 | M2: Tuần 10 | N2: Tuần 11 | O2: Tuần 12 | P2: Tuần 13 | Q2: Tuần 14 | R2: Tuần 15 | S2: Tuần 16 | T2: Tuần 17 | U2: Tuần 18 | V2: Tuần 19 | W2: Tuần 20 | X2: Tuần 21 | Y2: Tuần 22 | Z2: Tuần 23 | AA2: Tuần 24
B3: =IF('PV (Kế hoạch)'!B3="","",'PV (Kế hoạch)'!B3) -> 1 | C3: =IF('PV (Kế hoạch)'!C3="","",'PV (Kế hoạch)'!C3) -> Phân tích yêu cầu (Requirements Analysis) | D3: =IF(SUM('PV (Kế hoạch)'!$D3:D3)=0,"",ROUND(SUM('EV (Hoàn thành thực tế)'!$D3:D3)/SUM('PV (Kế hoạch)'!$D3:D3),2)) -> 0.99 | E3: =IF(SUM('PV (Kế hoạch)'!$D3:E3)=0,"",ROUND(SUM('EV (Hoàn thành thực tế)'!$D3:E3)/SUM('PV (Kế hoạch)'!$D3:E3),2)) -> 1 | F3: =IF(SUM('PV (Kế hoạch)'!$D3:F3)=0,"",ROUND(SUM('EV (Hoàn thành thực tế)'!$D3:F3)/SUM('PV (Kế hoạch)'!$D3:F3),2)) -> 1 | G3: =IF(SUM('PV (Kế hoạch)'!$D3:G3)=0,"",ROUND(SUM('EV (Hoàn thành thực tế)'!$D3:G3)/SUM('PV (Kế hoạch)'!$D3:G3),2)) -> 1 | H3: =IF(SUM('PV (Kế hoạch)'!$D3:H3)=0,"",ROUND(SUM('EV (Hoàn thành thực tế)'!$D3:H3)/SUM('PV (Kế hoạch)'!$D3:H3),2)) -> 1 | I3: =IF(SUM('PV (Kế hoạch)'!$D3:I3)=0,"",ROUND(SUM('EV (Hoàn thành thực tế)'!$D3:I3)/SUM('PV (Kế hoạch)'!$D3:I3),2)) -> 1 | J3: =IF(SUM('PV (Kế hoạch)'!$D3:J3)=0,"",ROUND(SUM('EV (Hoàn thành thực tế)'!$D3:J3)/SUM('PV (Kế hoạch)'!$D3:J3),2)) -> 1 | K3: =IF(SUM('PV (Kế hoạch)'!$D3:K3)=0,"",ROUND(SUM('EV (Hoàn thành thực tế)'!$D3:K3)/SUM('PV (Kế hoạch)'!$D3:K3),2)) -> 1 | ... AA3: =IF(SUM('PV (Kế hoạch)'!$D3:AA3)=0,"",ROUND(SUM('EV (Hoàn thành thực tế)'!$D3:AA3)/SUM('PV (Kế hoạch)'!$D3:AA3),2)) -> 1
B4: =IF('PV (Kế hoạch)'!B4="","",'PV (Kế hoạch)'!B4) -> 2 | C4: =IF('PV (Kế hoạch)'!C4="","",'PV (Kế hoạch)'!C4) -> Thiết kế hệ thống (System Design) | D4: =IF(SUM('PV (Kế hoạch)'!$D4:D4)=0,"",ROUND(SUM('EV (Hoàn thành thực tế)'!$D4:D4)/SUM('PV (Kế hoạch)'!$D4:D4),2)) | E4: =IF(SUM('PV (Kế hoạch)'!$D4:E4)=0,"",ROUND(SUM('EV (Hoàn thành thực tế)'!$D4:E4)/SUM('PV (Kế hoạch)'!$D4:E4),2)) | F4: =IF(SUM('PV (Kế hoạch)'!$D4:F4)=0,"",ROUND(SUM('EV (Hoàn thành thực tế)'!$D4:F4)/SUM('PV (Kế hoạch)'!$D4:F4),2)) -> 1 | G4: =IF(SUM('PV (Kế hoạch)'!$D4:G4)=0,"",ROUND(SUM('EV (Hoàn thành thực tế)'!$D4:G4)/SUM('PV (Kế hoạch)'!$D4:G4),2)) -> 0.99 | H4: =IF(SUM('PV (Kế hoạch)'!$D4:H4)=0,"",ROUND(SUM('EV (Hoàn thành thực tế)'!$D4:H4)/SUM('PV (Kế hoạch)'!$D4:H4),2)) -> 1 | I4: =IF(SUM('PV (Kế hoạch)'!$D4:I4)=0,"",ROUND(SUM('EV (Hoàn thành thực tế)'!$D4:I4)/SUM('PV (Kế hoạch)'!$D4:I4),2)) -> 1 | J4: =IF(SUM('PV (Kế hoạch)'!$D4:J4)=0,"",ROUND(SUM('EV (Hoàn thành thực tế)'!$D4:J4)/SUM('PV (Kế hoạch)'!$D4:J4),2)) -> 1 | K4: =IF(SUM('PV (Kế hoạch)'!$D4:K4)=0,"",ROUND(SUM('EV (Hoàn thành thực tế)'!$D4:K4)/SUM('PV (Kế hoạch)'!$D4:K4),2)) -> 1 | ... AA4: =IF(SUM('PV (Kế hoạch)'!$D4:AA4)=0,"",ROUND(SUM('EV (Hoàn thành thực tế)'!$D4:AA4)/SUM('PV (Kế hoạch)'!$D4:AA4),2)) -> 1
B5: =IF('PV (Kế hoạch)'!B5="","",'PV (Kế hoạch)'!B5) -> 3 | C5: =IF('PV (Kế hoạch)'!C5="","",'PV (Kế hoạch)'!C5) -> Thiết kế database (Database Design) | D5: =IF(SUM('PV (Kế hoạch)'!$D5:D5)=0,"",ROUND(SUM('EV (Hoàn thành thực tế)'!$D5:D5)/SUM('PV (Kế hoạch)'!$D5:D5),2)) | E5: =IF(SUM('PV (Kế hoạch)'!$D5:E5)=0,"",ROUND(SUM('EV (Hoàn thành thực tế)'!$D5:E5)/SUM('PV (Kế hoạch)'!$D5:E5),2)) | F5: =IF(SUM('PV (Kế hoạch)'!$D5:F5)=0,"",ROUND(SUM('EV (Hoàn thành thực tế)'!$D5:F5)/SUM('PV (Kế hoạch)'!$D5:F5),2)) | G5: =IF(SUM('PV (Kế hoạch)'!$D5:G5)=0,"",ROUND(SUM('EV (Hoàn thành thực tế)'!$D5:G5)/SUM('PV (Kế hoạch)'!$D5:G5),2)) -> 1 | H5: =IF(SUM('PV (Kế hoạch)'!$D5:H5)=0,"",ROUND(SUM('EV (Hoàn thành thực tế)'!$D5:H5)/SUM('PV (Kế hoạch)'!$D5:H5),2)) -> 1.01 | I5: =IF(SUM('PV (Kế hoạch)'!$D5:I5)=0,"",ROUND(SUM('EV (Hoàn thành thực tế)'!$D5:I5)/SUM('PV (Kế hoạch)'!$D5:I5),2)) -> 1 | J5: =IF(SUM('PV (Kế hoạch)'!$D5:J5)=0,"",ROUND(SUM('EV (Hoàn thành thực tế)'!$D5:J5)/SUM('PV (Kế hoạch)'!$D5:J5),2)) -> 1 | K5: =IF(SUM('PV (Kế hoạch)'!$D5:K5)=0,"",ROUND(SUM('EV (Hoàn thành thực tế)'!$D5:K5)/SUM('PV (Kế hoạch)'!$D5:K5),2)) -> 1 | ... AA5: =IF(SUM('PV (Kế hoạch)'!$D5:AA5)=0,"",ROUND(SUM('EV (Hoàn thành thực tế)'!$D5:AA5)/SUM('PV (Kế hoạch)'!$D5:AA5),2)) -> 1
B6: =IF('PV (Kế hoạch)'!B6="","",'PV (Kế hoạch)'!B6) -> 4 | C6: =IF('PV (Kế hoạch)'!C6="","",'PV (Kế hoạch)'!C6) -> Thiết kế UI/UX | D6: =IF(SUM('PV (Kế hoạch)'!$D6:D6)=0,"",ROUND(SUM('EV (Hoàn thành thực tế)'!$D6:D6)/SUM('PV (Kế hoạch)'!$D6:D6),2)) | E6: =IF(SUM('PV (Kế hoạch)'!$D6:E6)=0,"",ROUND(SUM('EV (Hoàn thành thực tế)'!$D6:E6)/SUM('PV (Kế hoạch)'!$D6:E6),2)) | F6: =IF(SUM('PV (Kế hoạch)'!$D6:F6)=0,"",ROUND(SUM('EV (Hoàn thành thực tế)'!$D6:F6)/SUM('PV (Kế hoạch)'!$D6:F6),2)) | G6: =IF(SUM('PV (Kế hoạch)'!$D6:G6)=0,"",ROUND(SUM('EV (Hoàn thành thực tế)'!$D6:G6)/SUM('PV (Kế hoạch)'!$D6:G6),2)) -> 1 | H6: =IF(SUM('PV (Kế hoạch)'!$D6:H6)=0,"",ROUND(SUM('EV (Hoàn thành thực tế)'!$D6:H6)/SUM('PV (Kế hoạch)'!$D6:H6),2)) -> 1 | I6: =IF(SUM('PV (Kế hoạch)'!$D6:I6)=0,"",ROUND(SUM('EV (Hoàn thành thực tế)'!$D6:I6)/SUM('PV (Kế hoạch)'!$D6:I6),2)) -> 1 | J6: =IF(SUM('PV (Kế hoạch)'!$D6:J6)=0,"",ROUND(SUM('EV (Hoàn thành thực tế)'!$D6:J6)/SUM('PV (Kế hoạch)'!$D6:J6),2)) -> 1 | K6: =IF(SUM('PV (Kế hoạch)'!$D6:K6)=0,"",ROUND(SUM('EV (Hoàn thành thực tế)'!$D6:K6)/SUM('PV (Kế hoạch)'!$D6:K6),2)) -> 1 | ... AA6: =IF(SUM('PV (Kế hoạch)'!$D6:AA6)=0,"",ROUND(SUM('EV (Hoàn thành thực tế)'!$D6:AA6)/SUM('PV (Kế hoạch)'!$D6:AA6),2)) -> 1
B7: =IF('PV (Kế hoạch)'!B7="","",'PV (Kế hoạch)'!B7) -> 5 | C7: =IF('PV (Kế hoạch)'!C7="","",'PV (Kế hoạch)'!C7) -> Phát triển Backend - Module User | D7: =IF(SUM('PV (Kế hoạch)'!$D7:D7)=0,"",ROUND(SUM('EV (Hoàn thành thực tế)'!$D7:D7)/SUM('PV (Kế hoạch)'!$D7:D7),2)) | E7: =IF(SUM('PV (Kế hoạch)'!$D7:E7)=0,"",ROUND(SUM('EV (Hoàn thành thực tế)'!$D7:E7)/SUM('PV (Kế hoạch)'!$D7:E7),2)) | F7: =IF(SUM('PV (Kế hoạch)'!$D7:F7)=0,"",ROUND(SUM('EV (Hoàn thành thực tế)'!$D7:F7)/SUM('PV (Kế hoạch)'!$D7:F7),2)) | G7: =IF(SUM('PV (Kế hoạch)'!$D7:G7)=0,"",ROUND(SUM('EV (Hoàn thành thực tế)'!$D7:G7)/SUM('PV (Kế hoạch)'!$D7:G7),2)) | H7: =IF(SUM('PV (Kế hoạch)'!$D7:H7)=0,"",ROUND(SUM('EV (Hoàn thành thực tế)'!$D7:H7)/SUM('PV (Kế hoạch)'!$D7:H7),2)) | I7: =IF(SUM('PV (Kế hoạch)'!$D7:I7)=0,"",ROUND(SUM('EV (Hoàn thành thực tế)'!$D7:I7)/SUM('PV (Kế hoạch)'!$D7:I7),2)) -> 1 | J7: =IF(SUM('PV (Kế hoạch)'!$D7:J7)=0,"",ROUND(SUM('EV (Hoàn thành thực tế)'!$D7:J7)/SUM('PV (Kế hoạch)'!$D7:J7),2)) -> 1 | K7: =IF(SUM('PV (Kế hoạch)'!$D7:K7)=0,"",ROUND(SUM('EV (Hoàn thành thực tế)'!$D7:K7)/SUM('PV (Kế hoạch)'!$D7:K7),2)) -> 1 | ... AA7: =IF(SUM('PV (Kế hoạch)'!$D7:AA7)=0,"",ROUND(SUM('EV (Hoàn thành thực tế)'!$D7:AA7)/SUM('PV (Kế hoạch)'!$D7:AA7),2)) -> 1
B8: =IF('PV (Kế hoạch)'!B8="","",'PV (Kế hoạch)'!B8) -> 6 | C8: =IF('PV (Kế hoạch)'!C8="","",'PV (Kế hoạch)'!C8) -> Phát triển Backend - Module Order | D8: =IF(SUM('PV (Kế hoạch)'!$D8:D8)=0,"",ROUND(SUM('EV (Hoàn thành thực tế)'!$D8:D8)/SUM('PV (Kế hoạch)'!$D8:D8),2)) | E8: =IF(SUM('PV (Kế hoạch)'!$D8:E8)=0,"",ROUND(SUM('EV (Hoàn thành thực tế)'!$D8:E8)/SUM('PV (Kế hoạch)'!$D8:E8),2)) | F8: =IF(SUM('PV (Kế hoạch)'!$D8:F8)=0,"",ROUND(SUM('EV (Hoàn thành thực tế)'!$D8:F8)/SUM('PV (Kế hoạch)'!$D8:F8),2)) | G8: =IF(SUM('PV (Kế hoạch)'!$D8:G8)=0,"",ROUND(SUM('EV (Hoàn thành thực tế)'!$D8:G8)/SUM('PV (Kế hoạch)'!$D8:G8),2)) | H8: =IF(SUM('PV (Kế hoạch)'!$D8:H8)=0,"",ROUND(SUM('EV (Hoàn thành thực tế)'!$D8:H8)/SUM('PV (Kế hoạch)'!$D8:H8),2)) | I8: =IF(SUM('PV (Kế hoạch)'!$D8:I8)=0,"",ROUND(SUM('EV (Hoàn thành thực tế)'!$D8:I8)/SUM('PV (Kế hoạch)'!$D8:I8),2)) | J8: =IF(SUM('PV (Kế hoạch)'!$D8:J8)=0,"",ROUND(SUM('EV (Hoàn thành thực tế)'!$D8:J8)/SUM('PV (Kế hoạch)'!$D8:J8),2)) | K8: =IF(SUM('PV (Kế hoạch)'!$D8:K8)=0,"",ROUND(SUM('EV (Hoàn thành thực tế)'!$D8:K8)/SUM('PV (Kế hoạch)'!$D8:K8),2)) -> 1 | ... AA8: =IF(SUM('PV (Kế hoạch)'!$D8:AA8)=0,"",ROUND(SUM('EV (Hoàn thành thực tế)'!$D8:AA8)/SUM('PV (Kế hoạch)'!$D8:AA8),2)) -> 1
B9: =IF('PV (Kế hoạch)'!B9="","",'PV (Kế hoạch)'!B9) -> 7 | C9: =IF('PV (Kế hoạch)'!C9="","",'PV (Kế hoạch)'!C9) -> Phát triển Backend - Module Payment | D9: =IF(SUM('PV (Kế hoạch)'!$D9:D9)=0,"",ROUND(SUM('EV (Hoàn thành thực tế)'!$D9:D9)/SUM('PV (Kế hoạch)'!$D9:D9),2)) | E9: =IF(SUM('PV (Kế hoạch)'!$D9:E9)=0,"",ROUND(SUM('EV (Hoàn thành thực tế)'!$D9:E9)/SUM('PV (Kế hoạch)'!$D9:E9),2)) | F9: =IF(SUM('PV (Kế hoạch)'!$D9:F9)=0,"",ROUND(SUM('EV (Hoàn thành thực tế)'!$D9:F9)/SUM('PV (Kế hoạch)'!$D9:F9),2)) | G9: =IF(SUM('PV (Kế hoạch)'!$D9:G9)=0,"",ROUND(SUM('EV (Hoàn thành thực tế)'!$D9:G9)/SUM('PV (Kế hoạch)'!$D9:G9),2)) | H9: =IF(SUM('PV (Kế hoạch)'!$D9:H9)=0,"",ROUND(SUM('EV (Hoàn thành thực tế)'!$D9:H9)/SUM('PV (Kế hoạch)'!$D9:H9),2)) | I9: =IF(SUM('PV (Kế hoạch)'!$D9:I9)=0,"",ROUND(SUM('EV (Hoàn thành thực tế)'!$D9:I9)/SUM('PV (Kế hoạch)'!$D9:I9),2)) | J9: =IF(SUM('PV (Kế hoạch)'!$D9:J9)=0,"",ROUND(SUM('EV (Hoàn thành thực tế)'!$D9:J9)/SUM('PV (Kế hoạch)'!$D9:J9),2)) | K9: =IF(SUM('PV (Kế hoạch)'!$D9:K9)=0,"",ROUND(SUM('EV (Hoàn thành thực tế)'!$D9:K9)/SUM('PV (Kế hoạch)'!$D9:K9),2)) | ... AA9: =IF(SUM('PV (Kế hoạch)'!$D9:AA9)=0,"",ROUND(SUM('EV (Hoàn thành thực tế)'!$D9:AA9)/SUM('PV (Kế hoạch)'!$D9:AA9),2)) -> 1
B10: =IF('PV (Kế hoạch)'!B10="","",'PV (Kế hoạch)'!B10) -> 8 | C10: =IF('PV (Kế hoạch)'!C10="","",'PV (Kế hoạch)'!C10) -> Phát triển Backend - Module Report | D10: =IF(SUM('PV (Kế hoạch)'!$D10:D10)=0,"",ROUND(SUM('EV (Hoàn thành thực tế)'!$D10:D10)/SUM('PV (Kế hoạch)'!$D10:D10),2)) | E10: =IF(SUM('PV (Kế hoạch)'!$D10:E10)=0,"",ROUND(SUM('EV (Hoàn thành thực tế)'!$D10:E10)/SUM('PV (Kế hoạch)'!$D10:E10),2)) | F10: =IF(SUM('PV (Kế hoạch)'!$D10:F10)=0,"",ROUND(SUM('EV (Hoàn thành thực tế)'!$D10:F10)/SUM('PV (Kế hoạch)'!$D10:F10),2)) | G10: =IF(SUM('PV (Kế hoạch)'!$D10:G10)=0,"",ROUND(SUM('EV (Hoàn thành thực tế)'!$D10:G10)/SUM('PV (Kế hoạch)'!$D10:G10),2)) | H10: =IF(SUM('PV (Kế hoạch)'!$D10:H10)=0,"",ROUND(SUM('EV (Hoàn thành thực tế)'!$D10:H10)/SUM('PV (Kế hoạch)'!$D10:H10),2)) | I10: =IF(SUM('PV (Kế hoạch)'!$D10:I10)=0,"",ROUND(SUM('EV (Hoàn thành thực tế)'!$D10:I10)/SUM('PV (Kế hoạch)'!$D10:I10),2)) | J10: =IF(SUM('PV (Kế hoạch)'!$D10:J10)=0,"",ROUND(SUM('EV (Hoàn thành thực tế)'!$D10:J10)/SUM('PV (Kế hoạch)'!$D10:J10),2)) | K10: =IF(SUM('PV (Kế hoạch)'!$D10:K10)=0,"",ROUND(SUM('EV (Hoàn thành thực tế)'!$D10:K10)/SUM('PV (Kế hoạch)'!$D10:K10),2)) | ... AA10: =IF(SUM('PV (Kế hoạch)'!$D10:AA10)=0,"",ROUND(SUM('EV (Hoàn thành thực tế)'!$D10:AA10)/SUM('PV (Kế hoạch)'!$D10:AA10),2)) -> 1
B11: =IF('PV (Kế hoạch)'!B11="","",'PV (Kế hoạch)'!B11) -> 9 | C11: =IF('PV (Kế hoạch)'!C11="","",'PV (Kế hoạch)'!C11) -> Phát triển Frontend - Trang chủ | D11: =IF(SUM('PV (Kế hoạch)'!$D11:D11)=0,"",ROUND(SUM('EV (Hoàn thành thực tế)'!$D11:D11)/SUM('PV (Kế hoạch)'!$D11:D11),2)) | E11: =IF(SUM('PV (Kế hoạch)'!$D11:E11)=0,"",ROUND(SUM('EV (Hoàn thành thực tế)'!$D11:E11)/SUM('PV (Kế hoạch)'!$D11:E11),2)) | F11: =IF(SUM('PV (Kế hoạch)'!$D11:F11)=0,"",ROUND(SUM('EV (Hoàn thành thực tế)'!$D11:F11)/SUM('PV (Kế hoạch)'!$D11:F11),2)) | G11: =IF(SUM('PV (Kế hoạch)'!$D11:G11)=0,"",ROUND(SUM('EV (Hoàn thành thực tế)'!$D11:G11)/SUM('PV (Kế hoạch)'!$D11:G11),2)) | H11: =IF(SUM('PV (Kế hoạch)'!$D11:H11)=0,"",ROUND(SUM('EV (Hoàn thành thực tế)'!$D11:H11)/SUM('PV (Kế hoạch)'!$D11:H11),2)) | I11: =IF(SUM('PV (Kế hoạch)'!$D11:I11)=0,"",ROUND(SUM('EV (Hoàn thành thực tế)'!$D11:I11)/SUM('PV (Kế hoạch)'!$D11:I11),2)) | J11: =IF(SUM('PV (Kế hoạch)'!$D11:J11)=0,"",ROUND(SUM('EV (Hoàn thành thực tế)'!$D11:J11)/SUM('PV (Kế hoạch)'!$D11:J11),2)) -> 1 | K11: =IF(SUM('PV (Kế hoạch)'!$D11:K11)=0,"",ROUND(SUM('EV (Hoàn thành thực tế)'!$D11:K11)/SUM('PV (Kế hoạch)'!$D11:K11),2)) -> 1.01 | ... AA11: =IF(SUM('PV (Kế hoạch)'!$D11:AA11)=0,"",ROUND(SUM('EV (Hoàn thành thực tế)'!$D11:AA11)/SUM('PV (Kế hoạch)'!$D11:AA11),2)) -> 1
B12: =IF('PV (Kế hoạch)'!B12="","",'PV (Kế hoạch)'!B12) -> 10 | C12: =IF('PV (Kế hoạch)'!C12="","",'PV (Kế hoạch)'!C12) -> Phát triển Frontend - Module User | D12: =IF(SUM('PV (Kế hoạch)'!$D12:D12)=0,"",ROUND(SUM('EV (Hoàn thành thực tế)'!$D12:D12)/SUM('PV (Kế hoạch)'!$D12:D12),2)) | E12: =IF(SUM('PV (Kế hoạch)'!$D12:E12)=0,"",ROUND(SUM('EV (Hoàn thành thực tế)'!$D12:E12)/SUM('PV (Kế hoạch)'!$D12:E12),2)) | F12: =IF(SUM('PV (Kế hoạch)'!$D12:F12)=0,"",ROUND(SUM('EV (Hoàn thành thực tế)'!$D12:F12)/SUM('PV (Kế hoạch)'!$D12:F12),2)) | G12: =IF(SUM('PV (Kế hoạch)'!$D12:G12)=0,"",ROUND(SUM('EV (Hoàn thành thực tế)'!$D12:G12)/SUM('PV (Kế hoạch)'!$D12:G12),2)) | H12: =IF(SUM('PV (Kế hoạch)'!$D12:H12)=0,"",ROUND(SUM('EV (Hoàn thành thực tế)'!$D12:H12)/SUM('PV (Kế hoạch)'!$D12:H12),2)) | I12: =IF(SUM('PV (Kế hoạch)'!$D12:I12)=0,"",ROUND(SUM('EV (Hoàn thành thực tế)'!$D12:I12)/SUM('PV (Kế hoạch)'!$D12:I12),2)) | J12: =IF(SUM('PV (Kế hoạch)'!$D12:J12)=0,"",ROUND(SUM('EV (Hoàn thành thực tế)'!$D12:J12)/SUM('PV (Kế hoạch)'!$D12:J12),2)) | K12: =IF(SUM('PV (Kế hoạch)'!$D12:K12)=0,"",ROUND(SUM('EV (Hoàn thành thực tế)'!$D12:K12)/SUM('PV (Kế hoạch)'!$D12:K12),2)) | ... AA12: =IF(SUM('PV (Kế hoạch)'!$D12:AA12)=0,"",ROUND(SUM('EV (Hoàn thành thực tế)'!$D12:AA12)/SUM('PV (Kế hoạch)'!$D12:AA12),2)) -> 1
B13: =IF('PV (Kế hoạch)'!B13="","",'PV (Kế hoạch)'!B13) -> 11 | C13: =IF('PV (Kế hoạch)'!C13="","",'PV (Kế hoạch)'!C13) -> Phát triển Frontend - Module Order | D13: =IF(SUM('PV (Kế hoạch)'!$D13:D13)=0,"",ROUND(SUM('EV (Hoàn thành thực tế)'!$D13:D13)/SUM('PV (Kế hoạch)'!$D13:D13),2)) | E13: =IF(SUM('PV (Kế hoạch)'!$D13:E13)=0,"",ROUND(SUM('EV (Hoàn thành thực tế)'!$D13:E13)/SUM('PV (Kế hoạch)'!$D13:E13),2)) | F13: =IF(SUM('PV (Kế hoạch)'!$D13:F13)=0,"",ROUND(SUM('EV (Hoàn thành thực tế)'!$D13:F13)/SUM('PV (Kế hoạch)'!$D13:F13),2)) | G13: =IF(SUM('PV (Kế hoạch)'!$D13:G13)=0,"",ROUND(SUM('EV (Hoàn thành thực tế)'!$D13:G13)/SUM('PV (Kế hoạch)'!$D13:G13),2)) | H13: =IF(SUM('PV (Kế hoạch)'!$D13:H13)=0,"",ROUND(SUM('EV (Hoàn thành thực tế)'!$D13:H13)/SUM('PV (Kế hoạch)'!$D13:H13),2)) | I13: =IF(SUM('PV (Kế hoạch)'!$D13:I13)=0,"",ROUND(SUM('EV (Hoàn thành thực tế)'!$D13:I13)/SUM('PV (Kế hoạch)'!$D13:I13),2)) | J13: =IF(SUM('PV (Kế hoạch)'!$D13:J13)=0,"",ROUND(SUM('EV (Hoàn thành thực tế)'!$D13:J13)/SUM('PV (Kế hoạch)'!$D13:J13),2)) | K13: =IF(SUM('PV (Kế hoạch)'!$D13:K13)=0,"",ROUND(SUM('EV (Hoàn thành thực tế)'!$D13:K13)/SUM('PV (Kế hoạch)'!$D13:K13),2)) | ... AA13: =IF(SUM('PV (Kế hoạch)'!$D13:AA13)=0,"",ROUND(SUM('EV (Hoàn thành thực tế)'!$D13:AA13)/SUM('PV (Kế hoạch)'!$D13:AA13),2)) -> 1
B14: =IF('PV (Kế hoạch)'!B14="","",'PV (Kế hoạch)'!B14) -> 12 | C14: =IF('PV (Kế hoạch)'!C14="","",'PV (Kế hoạch)'!C14) -> Phát triển Frontend - Module Payment | D14: =IF(SUM('PV (Kế hoạch)'!$D14:D14)=0,"",ROUND(SUM('EV (Hoàn thành thực tế)'!$D14:D14)/SUM('PV (Kế hoạch)'!$D14:D14),2)) | E14: =IF(SUM('PV (Kế hoạch)'!$D14:E14)=0,"",ROUND(SUM('EV (Hoàn thành thực tế)'!$D14:E14)/SUM('PV (Kế hoạch)'!$D14:E14),2)) | F14: =IF(SUM('PV (Kế hoạch)'!$D14:F14)=0,"",ROUND(SUM('EV (Hoàn thành thực tế)'!$D14:F14)/SUM('PV (Kế hoạch)'!$D14:F14),2)) | G14: =IF(SUM('PV (Kế hoạch)'!$D14:G14)=0,"",ROUND(SUM('EV (Hoàn thành thực tế)'!$D14:G14)/SUM('PV (Kế hoạch)'!$D14:G14),2)) | H14: =IF(SUM('PV (Kế hoạch)'!$D14:H14)=0,"",ROUND(SUM('EV (Hoàn thành thực tế)'!$D14:H14)/SUM('PV (Kế hoạch)'!$D14:H14),2)) | I14: =IF(SUM('PV (Kế hoạch)'!$D14:I14)=0,"",ROUND(SUM('EV (Hoàn thành thực tế)'!$D14:I14)/SUM('PV (Kế hoạch)'!$D14:I14),2)) | J14: =IF(SUM('PV (Kế hoạch)'!$D14:J14)=0,"",ROUND(SUM('EV (Hoàn thành thực tế)'!$D14:J14)/SUM('PV (Kế hoạch)'!$D14:J14),2)) | K14: =IF(SUM('PV (Kế hoạch)'!$D14:K14)=0,"",ROUND(SUM('EV (Hoàn thành thực tế)'!$D14:K14)/SUM('PV (Kế hoạch)'!$D14:K14),2)) | ... AA14: =IF(SUM('PV (Kế hoạch)'!$D14:AA14)=0,"",ROUND(SUM('EV (Hoàn thành thực tế)'!$D14:AA14)/SUM('PV (Kế hoạch)'!$D14:AA14),2)) -> 1
... B31: =IF('PV (Kế hoạch)'!B31="","",'PV (Kế hoạch)'!B31) -> 29 | C31: =IF('PV (Kế hoạch)'!C31="","",'PV (Kế hoạch)'!C31) | D31: =IF(SUM('PV (Kế hoạch)'!$D31:D31)=0,"",ROUND(SUM('EV (Hoàn thành thực tế)'!$D31:D31)/SUM('PV (Kế hoạch)'!$D31:D31),2)) | E31: =IF(SUM('PV (Kế hoạch)'!$D31:E31)=0,"",ROUND(SUM('EV (Hoàn thành thực tế)'!$D31:E31)/SUM('PV (Kế hoạch)'!$D31:E31),2)) | F31: =IF(SUM('PV (Kế hoạch)'!$D31:F31)=0,"",ROUND(SUM('EV (Hoàn thành thực tế)'!$D31:F31)/SUM('PV (Kế hoạch)'!$D31:F31),2)) | G31: =IF(SUM('PV (Kế hoạch)'!$D31:G31)=0,"",ROUND(SUM('EV (Hoàn thành thực tế)'!$D31:G31)/SUM('PV (Kế hoạch)'!$D31:G31),2)) | H31: =IF(SUM('PV (Kế hoạch)'!$D31:H31)=0,"",ROUND(SUM('EV (Hoàn thành thực tế)'!$D31:H31)/SUM('PV (Kế hoạch)'!$D31:H31),2)) | I31: =IF(SUM('PV (Kế hoạch)'!$D31:I31)=0,"",ROUND(SUM('EV (Hoàn thành thực tế)'!$D31:I31)/SUM('PV (Kế hoạch)'!$D31:I31),2)) | J31: =IF(SUM('PV (Kế hoạch)'!$D31:J31)=0,"",ROUND(SUM('EV (Hoàn thành thực tế)'!$D31:J31)/SUM('PV (Kế hoạch)'!$D31:J31),2)) | K31: =IF(SUM('PV (Kế hoạch)'!$D31:K31)=0,"",ROUND(SUM('EV (Hoàn thành thực tế)'!$D31:K31)/SUM('PV (Kế hoạch)'!$D31:K31),2)) | ... AA31: =IF(SUM('PV (Kế hoạch)'!$D31:AA31)=0,"",ROUND(SUM('EV (Hoàn thành thực tế)'!$D31:AA31)/SUM('PV (Kế hoạch)'!$D31:AA31),2))
A32: meet.google.com/wgq-kqad-utk | B32: =IF('PV (Kế hoạch)'!B32="","",'PV (Kế hoạch)'!B32) | C32: =IF('PV (Kế hoạch)'!C32="","",'PV (Kế hoạch)'!C32) -> Không chèn thêm dòng vào dưới dòng này | D32: =IF(SUM('PV (Kế hoạch)'!$D32:D32)=0,"",ROUND(SUM('EV (Hoàn thành thực tế)'!$D32:D32)/SUM('PV (Kế hoạch)'!$D32:D32),2)) | E32: =IF(SUM('PV (Kế hoạch)'!$D32:E32)=0,"",ROUND(SUM('EV (Hoàn thành thực tế)'!$D32:E32)/SUM('PV (Kế hoạch)'!$D32:E32),2)) | F32: =IF(SUM('PV (Kế hoạch)'!$D32:F32)=0,"",ROUND(SUM('EV (Hoàn thành thực tế)'!$D32:F32)/SUM('PV (Kế hoạch)'!$D32:F32),2)) | G32: =IF(SUM('PV (Kế hoạch)'!$D32:G32)=0,"",ROUND(SUM('EV (Hoàn thành thực tế)'!$D32:G32)/SUM('PV (Kế hoạch)'!$D32:G32),2)) | H32: =IF(SUM('PV (Kế hoạch)'!$D32:H32)=0,"",ROUND(SUM('EV (Hoàn thành thực tế)'!$D32:H32)/SUM('PV (Kế hoạch)'!$D32:H32),2)) | I32: =IF(SUM('PV (Kế hoạch)'!$D32:I32)=0,"",ROUND(SUM('EV (Hoàn thành thực tế)'!$D32:I32)/SUM('PV (Kế hoạch)'!$D32:I32),2)) | J32: =IF(SUM('PV (Kế hoạch)'!$D32:J32)=0,"",ROUND(SUM('EV (Hoàn thành thực tế)'!$D32:J32)/SUM('PV (Kế hoạch)'!$D32:J32),2)) | K32: =IF(SUM('PV (Kế hoạch)'!$D32:K32)=0,"",ROUND(SUM('EV (Hoàn thành thực tế)'!$D32:K32)/SUM('PV (Kế hoạch)'!$D32:K32),2)) | ... AA32: =IF(SUM('PV (Kế hoạch)'!$D32:AA32)=0,"",ROUND(SUM('EV (Hoàn thành thực tế)'!$D32:AA32)/SUM('PV (Kế hoạch)'!$D32:AA32),2))
C33: TỔNG CỘNG | D33: =IF(SUM('PV (Kế hoạch)'!$D33:D33)=0,"",ROUND(SUM('EV (Hoàn thành thực tế)'!$D33:D33)/SUM('PV (Kế hoạch)'!$D33:D33),2)) -> 0.99 | E33: =IF(SUM('PV (Kế hoạch)'!$D33:E33)=0,"",ROUND(SUM('EV (Hoàn thành thực tế)'!$D33:E33)/SUM('PV (Kế hoạch)'!$D33:E33),2)) -> 1 | F33: =IF(SUM('PV (Kế hoạch)'!$D33:F33)=0,"",ROUND(SUM('EV (Hoàn thành thực tế)'!$D33:F33)/SUM('PV (Kế hoạch)'!$D33:F33),2)) -> 1 | G33: =IF(SUM('PV (Kế hoạch)'!$D33:G33)=0,"",ROUND(SUM('EV (Hoàn thành thực tế)'!$D33:G33)/SUM('PV (Kế hoạch)'!$D33:G33),2)) -> 1 | H33: =IF(SUM('PV (Kế hoạch)'!$D33:H33)=0,"",ROUND(SUM('EV (Hoàn thành thực tế)'!$D33:H33)/SUM('PV (Kế hoạch)'!$D33:H33),2)) -> 1 | I33: =IF(SUM('PV (Kế hoạch)'!$D33:I33)=0,"",ROUND(SUM('EV (Hoàn thành thực tế)'!$D33:I33)/SUM('PV (Kế hoạch)'!$D33:I33),2)) -> 1 | J33: =IF(SUM('PV (Kế hoạch)'!$D33:J33)=0,"",ROUND(SUM('EV (Hoàn thành thực tế)'!$D33:J33)/SUM('PV (Kế hoạch)'!$D33:J33),2)) -> 1 | K33: =IF(SUM('PV (Kế hoạch)'!$D33:K33)=0,"",ROUND(SUM('EV (Hoàn thành thực tế)'!$D33:K33)/SUM('PV (Kế hoạch)'!$D33:K33),2)) -> 1 | ... AA33: =IF(SUM('PV (Kế hoạch)'!$D33:AA33)=0,"",ROUND(SUM('EV (Hoàn thành thực tế)'!$D33:AA33)/SUM('PV (Kế hoạch)'!$D33:AA33),2)) -> 0.77

Sheet EV (Hoàn thành thực tế)
B1: EV - EARNED VALUE (CÔNG SỐ HOÀN THÀNH THỰC TẾ TỪNG TUẦN) (md)
B2: No. | C2: Hạng mục công việc | D2: Tuần 1 | E2: Tuần 2 | F2: Tuần 3 | G2: Tuần 4 | H2: Tuần 5 | I2: Tuần 6 | J2: Tuần 7 | K2: Tuần 8 | L2: Tuần 9 | M2: Tuần 10 | N2: Tuần 11 | O2: Tuần 12 | P2: Tuần 13 | Q2: Tuần 14 | R2: Tuần 15 | S2: Tuần 16 | T2: Tuần 17 | U2: Tuần 18 | V2: Tuần 19 | W2: Tuần 20 | X2: Tuần 21 | Y2: Tuần 22 | Z2: Tuần 23 | AA2: Tuần 24 | AB2: Tổng
B3: =IF('PV (Kế hoạch)'!B3="","",'PV (Kế hoạch)'!B3) -> 1 | C3: =IF('PV (Kế hoạch)'!C3="","",'PV (Kế hoạch)'!C3) -> Phân tích yêu cầu (Requirements Analysis) | D3: ='EV (Tiến độ lũy kế)'!D3*SUM('PV (Kế hoạch)'!$D3:$AA3) -> 4.94 | E3: ='EV (Tiến độ lũy kế)'!E3*SUM('PV (Kế hoạch)'!$D3:$AA3)-SUM($D3:D3) -> 5.07 | F3: ='EV (Tiến độ lũy kế)'!F3*SUM('PV (Kế hoạch)'!$D3:$AA3)-SUM($D3:E3) -> 2.99 | G3: ='EV (Tiến độ lũy kế)'!G3*SUM('PV (Kế hoạch)'!$D3:$AA3)-SUM($D3:F3) -> 0 | H3: ='EV (Tiến độ lũy kế)'!H3*SUM('PV (Kế hoạch)'!$D3:$AA3)-SUM($D3:G3) -> 0 | I3: ='EV (Tiến độ lũy kế)'!I3*SUM('PV (Kế hoạch)'!$D3:$AA3)-SUM($D3:H3) -> 0 | J3: ='EV (Tiến độ lũy kế)'!J3*SUM('PV (Kế hoạch)'!$D3:$AA3)-SUM($D3:I3) -> 0 | K3: ='EV (Tiến độ lũy kế)'!K3*SUM('PV (Kế hoạch)'!$D3:$AA3)-SUM($D3:J3) -> 0 | L3: ='EV (Tiến độ lũy kế)'!L3*SUM('PV (Kế hoạch)'!$D3:$AA3)-SUM($D3:K3) -> 0 | ... AA3: ='EV (Tiến độ lũy kế)'!AA3*SUM('PV (Kế hoạch)'!$D3:$AA3)-SUM($D3:Z3) -> 0 | AB3: =SUM(D3:AA3) -> 13
B4: =IF('PV (Kế hoạch)'!B4="","",'PV (Kế hoạch)'!B4) -> 2 | C4: =IF('PV (Kế hoạch)'!C4="","",'PV (Kế hoạch)'!C4) -> Thiết kế hệ thống (System Design) | D4: ='EV (Tiến độ lũy kế)'!D4*SUM('PV (Kế hoạch)'!$D4:$AA4) -> 0 | E4: ='EV (Tiến độ lũy kế)'!E4*SUM('PV (Kế hoạch)'!$D4:$AA4)-SUM($D4:D4) -> 0 | F4: ='EV (Tiến độ lũy kế)'!F4*SUM('PV (Kế hoạch)'!$D4:$AA4)-SUM($D4:E4) -> 3 | G4: ='EV (Tiến độ lũy kế)'!G4*SUM('PV (Kế hoạch)'!$D4:$AA4)-SUM($D4:F4) -> 4.95 | H4: ='EV (Tiến độ lũy kế)'!H4*SUM('PV (Kế hoạch)'!$D4:$AA4)-SUM($D4:G4) -> 5.1 | I4: ='EV (Tiến độ lũy kế)'!I4*SUM('PV (Kế hoạch)'!$D4:$AA4)-SUM($D4:H4) -> 1.95 | J4: ='EV (Tiến độ lũy kế)'!J4*SUM('PV (Kế hoạch)'!$D4:$AA4)-SUM($D4:I4) -> 0 | K4: ='EV (Tiến độ lũy kế)'!K4*SUM('PV (Kế hoạch)'!$D4:$AA4)-SUM($D4:J4) -> 0 | L4: ='EV (Tiến độ lũy kế)'!L4*SUM('PV (Kế hoạch)'!$D4:$AA4)-SUM($D4:K4) -> 0 | ... AA4: ='EV (Tiến độ lũy kế)'!AA4*SUM('PV (Kế hoạch)'!$D4:$AA4)-SUM($D4:Z4) -> 0 | AB4: =SUM(D4:AA4) -> 15
B5: =IF('PV (Kế hoạch)'!B5="","",'PV (Kế hoạch)'!B5) -> 3 | C5: =IF('PV (Kế hoạch)'!C5="","",'PV (Kế hoạch)'!C5) -> Thiết kế database (Database Design) | D5: ='EV (Tiến độ lũy kế)'!D5*SUM('PV (Kế hoạch)'!$D5:$AA5) -> 0 | E5: ='EV (Tiến độ lũy kế)'!E5*SUM('PV (Kế hoạch)'!$D5:$AA5)-SUM($D5:D5) -> 0 | F5: ='EV (Tiến độ lũy kế)'!F5*SUM('PV (Kế hoạch)'!$D5:$AA5)-SUM($D5:E5) -> 0 | G5: ='EV (Tiến độ lũy kế)'!G5*SUM('PV (Kế hoạch)'!$D5:$AA5)-SUM($D5:F5) -> 2 | H5: ='EV (Tiến độ lũy kế)'!H5*SUM('PV (Kế hoạch)'!$D5:$AA5)-SUM($D5:G5) -> 3.04 | I5: ='EV (Tiến độ lũy kế)'!I5*SUM('PV (Kế hoạch)'!$D5:$AA5)-SUM($D5:H5) -> 2.96 | J5: ='EV (Tiến độ lũy kế)'!J5*SUM('PV (Kế hoạch)'!$D5:$AA5)-SUM($D5:I5) -> 0 | K5: ='EV (Tiến độ lũy kế)'!K5*SUM('PV (Kế hoạch)'!$D5:$AA5)-SUM($D5:J5) -> 0 | L5: ='EV (Tiến độ lũy kế)'!L5*SUM('PV (Kế hoạch)'!$D5:$AA5)-SUM($D5:K5) -> 0 | ... AA5: ='EV (Tiến độ lũy kế)'!AA5*SUM('PV (Kế hoạch)'!$D5:$AA5)-SUM($D5:Z5) -> 0 | AB5: =SUM(D5:AA5) -> 8
B6: =IF('PV (Kế hoạch)'!B6="","",'PV (Kế hoạch)'!B6) -> 4 | C6: =IF('PV (Kế hoạch)'!C6="","",'PV (Kế hoạch)'!C6) -> Thiết kế UI/UX | D6: ='EV (Tiến độ lũy kế)'!D6*SUM('PV (Kế hoạch)'!$D6:$AA6) -> 0 | E6: ='EV (Tiến độ lũy kế)'!E6*SUM('PV (Kế hoạch)'!$D6:$AA6)-SUM($D6:D6) -> 0 | F6: ='EV (Tiến độ lũy kế)'!F6*SUM('PV (Kế hoạch)'!$D6:$AA6)-SUM($D6:E6) -> 0 | G6: ='EV (Tiến độ lũy kế)'!G6*SUM('PV (Kế hoạch)'!$D6:$AA6)-SUM($D6:F6) -> 2 | H6: ='EV (Tiến độ lũy kế)'!H6*SUM('PV (Kế hoạch)'!$D6:$AA6)-SUM($D6:G6) -> 3 | I6: ='EV (Tiến độ lũy kế)'!I6*SUM('PV (Kế hoạch)'!$D6:$AA6)-SUM($D6:H6) -> 3 | J6: ='EV (Tiến độ lũy kế)'!J6*SUM('PV (Kế hoạch)'!$D6:$AA6)-SUM($D6:I6) -> 2 | K6: ='EV (Tiến độ lũy kế)'!K6*SUM('PV (Kế hoạch)'!$D6:$AA6)-SUM($D6:J6) -> 0 | L6: ='EV (Tiến độ lũy kế)'!L6*SUM('PV (Kế hoạch)'!$D6:$AA6)-SUM($D6:K6) -> 0 | ... AA6: ='EV (Tiến độ lũy kế)'!AA6*SUM('PV (Kế hoạch)'!$D6:$AA6)-SUM($D6:Z6) -> 0 | AB6: =SUM(D6:AA6) -> 10
B7: =IF('PV (Kế hoạch)'!B7="","",'PV (Kế hoạch)'!B7) -> 5 | C7: =IF('PV (Kế hoạch)'!C7="","",'PV (Kế hoạch)'!C7) -> Phát triển Backend - Module User | D7: ='EV (Tiến độ lũy kế)'!D7*SUM('PV (Kế hoạch)'!$D7:$AA7) -> 0 | E7: ='EV (Tiến độ lũy kế)'!E7*SUM('PV (Kế hoạch)'!$D7:$AA7)-SUM($D7:D7) -> 0 | F7: ='EV (Tiến độ lũy kế)'!F7*SUM('PV (Kế hoạch)'!$D7:$AA7)-SUM($D7:E7) -> 0 | G7: ='EV (Tiến độ lũy kế)'!G7*SUM('PV (Kế hoạch)'!$D7:$AA7)-SUM($D7:F7) -> 0 | H7: ='EV (Tiến độ lũy kế)'!H7*SUM('PV (Kế hoạch)'!$D7:$AA7)-SUM($D7:G7) -> 0 | I7: ='EV (Tiến độ lũy kế)'!I7*SUM('PV (Kế hoạch)'!$D7:$AA7)-SUM($D7:H7) -> 2 | J7: ='EV (Tiến độ lũy kế)'!J7*SUM('PV (Kế hoạch)'!$D7:$AA7)-SUM($D7:I7) -> 5 | K7: ='EV (Tiến độ lũy kế)'!K7*SUM('PV (Kế hoạch)'!$D7:$AA7)-SUM($D7:J7) -> 5 | L7: ='EV (Tiến độ lũy kế)'!L7*SUM('PV (Kế hoạch)'!$D7:$AA7)-SUM($D7:K7) -> 5 | ... AA7: ='EV (Tiến độ lũy kế)'!AA7*SUM('PV (Kế hoạch)'!$D7:$AA7)-SUM($D7:Z7) -> 0 | AB7: =SUM(D7:AA7) -> 20
B8: =IF('PV (Kế hoạch)'!B8="","",'PV (Kế hoạch)'!B8) -> 6 | C8: =IF('PV (Kế hoạch)'!C8="","",'PV (Kế hoạch)'!C8) -> Phát triển Backend - Module Order | D8: ='EV (Tiến độ lũy kế)'!D8*SUM('PV (Kế hoạch)'!$D8:$AA8) -> 0 | E8: ='EV (Tiến độ lũy kế)'!E8*SUM('PV (Kế hoạch)'!$D8:$AA8)-SUM($D8:D8) -> 0 | F8: ='EV (Tiến độ lũy kế)'!F8*SUM('PV (Kế hoạch)'!$D8:$AA8)-SUM($D8:E8) -> 0 | G8: ='EV (Tiến độ lũy kế)'!G8*SUM('PV (Kế hoạch)'!$D8:$AA8)-SUM($D8:F8) -> 0 | H8: ='EV (Tiến độ lũy kế)'!H8*SUM('PV (Kế hoạch)'!$D8:$AA8)-SUM($D8:G8) -> 0 | I8: ='EV (Tiến độ lũy kế)'!I8*SUM('PV (Kế hoạch)'!$D8:$AA8)-SUM($D8:H8) -> 0 | J8: ='EV (Tiến độ lũy kế)'!J8*SUM('PV (Kế hoạch)'!$D8:$AA8)-SUM($D8:I8) -> 0 | K8: ='EV (Tiến độ lũy kế)'!K8*SUM('PV (Kế hoạch)'!$D8:$AA8)-SUM($D8:J8) -> 2 | L8: ='EV (Tiến độ lũy kế)'!L8*SUM('PV (Kế hoạch)'!$D8:$AA8)-SUM($D8:K8) -> 5 | ... AA8: ='EV (Tiến độ lũy kế)'!AA8*SUM('PV (Kế hoạch)'!$D8:$AA8)-SUM($D8:Z8) -> 0 | AB8: =SUM(D8:AA8) -> 20
B9: =IF('PV (Kế hoạch)'!B9="","",'PV (Kế hoạch)'!B9) -> 7 | C9: =IF('PV (Kế hoạch)'!C9="","",'PV (Kế hoạch)'!C9) -> Phát triển Backend - Module Payment | D9: ='EV (Tiến độ lũy kế)'!D9*SUM('PV (Kế hoạch)'!$D9:$AA9) -> 0 | E9: ='EV (Tiến độ lũy kế)'!E9*SUM('PV (Kế hoạch)'!$D9:$AA9)-SUM($D9:D9) -> 0 | F9: ='EV (Tiến độ lũy kế)'!F9*SUM('PV (Kế hoạch)'!$D9:$AA9)-SUM($D9:E9) -> 0 | G9: ='EV (Tiến độ lũy kế)'!G9*SUM('PV (Kế hoạch)'!$D9:$AA9)-SUM($D9:F9) -> 0 | H9: ='EV (Tiến độ lũy kế)'!H9*SUM('PV (Kế hoạch)'!$D9:$AA9)-SUM($D9:G9) -> 0 | I9: ='EV (Tiến độ lũy kế)'!I9*SUM('PV (Kế hoạch)'!$D9:$AA9)-SUM($D9:H9) -> 0 | J9: ='EV (Tiến độ lũy kế)'!J9*SUM('PV (Kế hoạch)'!$D9:$AA9)-SUM($D9:I9) -> 0 | K9: ='EV (Tiến độ lũy kế)'!K9*SUM('PV (Kế hoạch)'!$D9:$AA9)-SUM($D9:J9) -> 0 | L9: ='EV (Tiến độ lũy kế)'!L9*SUM('PV (Kế hoạch)'!$D9:$AA9)-SUM($D9:K9) -> 0 | ... AA9: ='EV (Tiến độ lũy kế)'!AA9*SUM('PV (Kế hoạch)'!$D9:$AA9)-SUM($D9:Z9) -> 0 | AB9: =SUM(D9:AA9) -> 17
B10: =IF('PV (Kế hoạch)'!B10="","",'PV (Kế hoạch)'!B10) -> 8 | C10: =IF('PV (Kế hoạch)'!C10="","",'PV (Kế hoạch)'!C10) -> Phát triển Backend - Module Report | D10: ='EV (Tiến độ lũy kế)'!D10*SUM('PV (Kế hoạch)'!$D10:$AA10) -> 0 | E10: ='EV (Tiến độ lũy kế)'!E10*SUM('PV (Kế hoạch)'!$D10:$AA10)-SUM($D10:D10) -> 0 | F10: ='EV (Tiến độ lũy kế)'!F10*SUM('PV (Kế hoạch)'!$D10:$AA10)-SUM($D10:E10) -> 0 | G10: ='EV (Tiến độ lũy kế)'!G10*SUM('PV (Kế hoạch)'!$D10:$AA10)-SUM($D10:F10) -> 0 | H10: ='EV (Tiến độ lũy kế)'!H10*SUM('PV (Kế hoạch)'!$D10:$AA10)-SUM($D10:G10) -> 0 | I10: ='EV (Tiến độ lũy kế)'!I10*SUM('PV (Kế hoạch)'!$D10:$AA10)-SUM($D10:H10) -> 0 | J10: ='EV (Tiến độ lũy kế)'!J10*SUM('PV (Kế hoạch)'!$D10:$AA10)-SUM($D10:I10) -> 0 | K10: ='EV (Tiến độ lũy kế)'!K10*SUM('PV (Kế hoạch)'!$D10:$AA10)-SUM($D10:J10) -> 0 | L10: ='EV (Tiến độ lũy kế)'!L10*SUM('PV (Kế hoạch)'!$D10:$AA10)-SUM($D10:K10) -> 0 | ... AA10: ='EV (Tiến độ lũy kế)'!AA10*SUM('PV (Kế hoạch)'!$D10:$AA10)-SUM($D10:Z10) -> 0 | AB10: =SUM(D10:AA10) -> 15
B11: =IF('PV (Kế hoạch)'!B11="","",'PV (Kế hoạch)'!B11) -> 9 | C11: =IF('PV (Kế hoạch)'!C11="","",'PV (Kế hoạch)'!C11) -> Phát triển Frontend - Trang chủ | D11: ='EV (Tiến độ lũy kế)'!D11*SUM('PV (Kế hoạch)'!$D11:$AA11) -> 0 | E11: ='EV (Tiến độ lũy kế)'!E11*SUM('PV (Kế hoạch)'!$D11:$AA11)-SUM($D11:D11) -> 0 | F11: ='EV (Tiến độ lũy kế)'!F11*SUM('PV (Kế hoạch)'!$D11:$AA11)-SUM($D11:E11) -> 0 | G11: ='EV (Tiến độ lũy kế)'!G11*SUM('PV (Kế hoạch)'!$D11:$AA11)-SUM($D11:F11) -> 0 | H11: ='EV (Tiến độ lũy kế)'!H11*SUM('PV (Kế hoạch)'!$D11:$AA11)-SUM($D11:G11) -> 0 | I11: ='EV (Tiến độ lũy kế)'!I11*SUM('PV (Kế hoạch)'!$D11:$AA11)-SUM($D11:H11) -> 0 | J11: ='EV (Tiến độ lũy kế)'!J11*SUM('PV (Kế hoạch)'!$D11:$AA11)-SUM($D11:I11) -> 2 | K11: ='EV (Tiến độ lũy kế)'!K11*SUM('PV (Kế hoạch)'!$D11:$AA11)-SUM($D11:J11) -> 3.04 | L11: ='EV (Tiến độ lũy kế)'!L11*SUM('PV (Kế hoạch)'!$D11:$AA11)-SUM($D11:K11) -> 2.96 | ... AA11: ='EV (Tiến độ lũy kế)'!AA11*SUM('PV (Kế hoạch)'!$D11:$AA11)-SUM($D11:Z11) -> 0 | AB11: =SUM(D11:AA11) -> 8
B12: =IF('PV (Kế hoạch)'!B12="","",'PV (Kế hoạch)'!B12) -> 10 | C12: =IF('PV (Kế hoạch)'!C12="","",'PV (Kế hoạch)'!C12) -> Phát triển Frontend - Module User | D12: ='EV (Tiến độ lũy kế)'!D12*SUM('PV (Kế hoạch)'!$D12:$AA12) -> 0 | E12: ='EV (Tiến độ lũy kế)'!E12*SUM('PV (Kế hoạch)'!$D12:$AA12)-SUM($D12:D12) -> 0 | F12: ='EV (Tiến độ lũy kế)'!F12*SUM('PV (Kế hoạch)'!$D12:$AA12)-SUM($D12:E12) -> 0 | G12: ='EV (Tiến độ lũy kế)'!G12*SUM('PV (Kế hoạch)'!$D12:$AA12)-SUM($D12:F12) -> 0 | H12: ='EV (Tiến độ lũy kế)'!H12*SUM('PV (Kế hoạch)'!$D12:$AA12)-SUM($D12:G12) -> 0 | I12: ='EV (Tiến độ lũy kế)'!I12*SUM('PV (Kế hoạch)'!$D12:$AA12)-SUM($D12:H12) -> 0 | J12: ='EV (Tiến độ lũy kế)'!J12*SUM('PV (Kế hoạch)'!$D12:$AA12)-SUM($D12:I12) -> 0 | K12: ='EV (Tiến độ lũy kế)'!K12*SUM('PV (Kế hoạch)'!$D12:$AA12)-SUM($D12:J12) -> 0 | L12: ='EV (Tiến độ lũy kế)'!L12*SUM('PV (Kế hoạch)'!$D12:$AA12)-SUM($D12:K12) -> 1.95 | ... AA12: ='EV (Tiến độ lũy kế)'!AA12*SUM('PV (Kế hoạch)'!$D12:$AA12)-SUM($D12:Z12) -> 0 | AB12: =SUM(D12:AA12) -> 15
B13: =IF('PV (Kế hoạch)'!B13="","",'PV (Kế hoạch)'!B13) -> 11 | C13: =IF('PV (Kế hoạch)'!C13="","",'PV (Kế hoạch)'!C13) -> Phát triển Frontend - Module Order | D13: ='EV (Tiến độ lũy kế)'!D13*SUM('PV (Kế hoạch)'!$D13:$AA13) -> 0 | E13: ='EV (Tiến độ lũy kế)'!E13*SUM('PV (Kế hoạch)'!$D13:$AA13)-SUM($D13:D13) -> 0 | F13: ='EV (Tiến độ lũy kế)'!F13*SUM('PV (Kế hoạch)'!$D13:$AA13)-SUM($D13:E13) -> 0 | G13: ='EV (Tiến độ lũy kế)'!G13*SUM('PV (Kế hoạch)'!$D13:$AA13)-SUM($D13:F13) -> 0 | H13: ='EV (Tiến độ lũy kế)'!H13*SUM('PV (Kế hoạch)'!$D13:$AA13)-SUM($D13:G13) -> 0 | I13: ='EV (Tiến độ lũy kế)'!I13*SUM('PV (Kế hoạch)'!$D13:$AA13)-SUM($D13:H13) -> 0 | J13: ='EV (Tiến độ lũy kế)'!J13*SUM('PV (Kế hoạch)'!$D13:$AA13)-SUM($D13:I13) -> 0 | K13: ='EV (Tiến độ lũy kế)'!K13*SUM('PV (Kế hoạch)'!$D13:$AA13)-SUM($D13:J13) -> 0 | L13: ='EV (Tiến độ lũy kế)'!L13*SUM('PV (Kế hoạch)'!$D13:$AA13)-SUM($D13:K13) -> 0 | ... AA13: ='EV (Tiến độ lũy kế)'!AA13*SUM('PV (Kế hoạch)'!$D13:$AA13)-SUM($D13:Z13) -> 0 | AB13: =SUM(D13:AA13) -> 15
B14: =IF('PV (Kế hoạch)'!B14="","",'PV (Kế hoạch)'!B14) -> 12 | C14: =IF('PV (Kế hoạch)'!C14="","",'PV (Kế hoạch)'!C14) -> Phát triển Frontend - Module Payment | D14: ='EV (Tiến độ lũy kế)'!D14*SUM('PV (Kế hoạch)'!$D14:$AA14) -> 0 | E14: ='EV (Tiến độ lũy kế)'!E14*SUM('PV (Kế hoạch)'!$D14:$AA14)-SUM($D14:D14) -> 0 | F14: ='EV (Tiến độ lũy kế)'!F14*SUM('PV (Kế hoạch)'!$D14:$AA14)-SUM($D14:E14) -> 0 | G14: ='EV (Tiến độ lũy kế)'!G14*SUM('PV (Kế hoạch)'!$D14:$AA14)-SUM($D14:F14) -> 0 | H14: ='EV (Tiến độ lũy kế)'!H14*SUM('PV (Kế hoạch)'!$D14:$AA14)-SUM($D14:G14) -> 0 | I14: ='EV (Tiến độ lũy kế)'!I14*SUM('PV (Kế hoạch)'!$D14:$AA14)-SUM($D14:H14) -> 0 | J14: ='EV (Tiến độ lũy kế)'!J14*SUM('PV (Kế hoạch)'!$D14:$AA14)-SUM($D14:I14) -> 0 | K14: ='EV (Tiến độ lũy kế)'!K14*SUM('PV (Kế hoạch)'!$D14:$AA14)-SUM($D14:J14) -> 0 | L14: ='EV (Tiến độ lũy kế)'!L14*SUM('PV (Kế hoạch)'!$D14:$AA14)-SUM($D14:K14) -> 0 | ... AA14: ='EV (Tiến độ lũy kế)'!AA14*SUM('PV (Kế hoạch)'!$D14:$AA14)-SUM($D14:Z14) -> 0 | AB14: =SUM(D14:AA14) -> 12
... B27: =IF('PV (Kế hoạch)'!B27="","",'PV (Kế hoạch)'!B27) -> 25 | C27: =IF('PV (Kế hoạch)'!C27="","",'PV (Kế hoạch)'!C27) -> Go-live Support | D27: ='EV (Tiến độ lũy kế)'!D27*SUM('PV (Kế hoạch)'!$D27:$AA27) -> 0 | E27: ='EV (Tiến độ lũy kế)'!E27*SUM('PV (Kế hoạch)'!$D27:$AA27)-SUM($D27:D27) -> 0 | F27: ='EV (Tiến độ lũy kế)'!F27*SUM('PV (Kế hoạch)'!$D27:$AA27)-SUM($D27:E27) -> 0 | G27: ='EV (Tiến độ lũy kế)'!G27*SUM('PV (Kế hoạch)'!$D27:$AA27)-SUM($D27:F27) -> 0 | H27: ='EV (Tiến độ lũy kế)'!H27*SUM('PV (Kế hoạch)'!$D27:$AA27)-SUM($D27:G27) -> 0 | I27: ='EV (Tiến độ lũy kế)'!I27*SUM('PV (Kế hoạch)'!$D27:$AA27)-SUM($D27:H27) -> 0 | J27: ='EV (Tiến độ lũy kế)'!J27*SUM('PV (Kế hoạch)'!$D27:$AA27)-SUM($D27:I27) -> 0 | K27: ='EV (Tiến độ lũy kế)'!K27*SUM('PV (Kế hoạch)'!$D27:$AA27)-SUM($D27:J27) -> 0 | L27: ='EV (Tiến độ lũy kế)'!L27*SUM('PV (Kế hoạch)'!$D27:$AA27)-SUM($D27:K27) -> 0 | ... AA27: ='EV (Tiến độ lũy kế)'!AA27*SUM('PV (Kế hoạch)'!$D27:$AA27)-SUM($D27:Z27) -> 0 | AB27: =SUM(D27:AA27) -> 0
B28: =IF('PV (Kế hoạch)'!B28="","",'PV (Kế hoạch)'!B28) -> 26 | C28: =IF('PV (Kế hoạch)'!C28="","",'PV (Kế hoạch)'!C28) | AB28: =SUM(D28:AA28) -> 0
B29: =IF('PV (Kế hoạch)'!B29="","",'PV (Kế hoạch)'!B29) -> 27 | C29: =IF('PV (Kế hoạch)'!C29="","",'PV (Kế hoạch)'!C29) | AB29: =SUM(D29:AA29) -> 0
B30: =IF('PV (Kế hoạch)'!B30="","",'PV (Kế hoạch)'!B30) -> 28 | C30: =IF('PV (Kế hoạch)'!C30="","",'PV (Kế hoạch)'!C30) | AB30: =SUM(D30:AA30) -> 0
B31: =IF('PV (Kế hoạch)'!B31="","",'PV (Kế hoạch)'!B31) -> 29 | C31: =IF('PV (Kế hoạch)'!C31="","",'PV (Kế hoạch)'!C31) | AB31: =SUM(D31:AA31) -> 0
B32: =IF('PV (Kế hoạch)'!B32="","",'PV (Kế hoạch)'!B32) | C32: =IF('PV (Kế hoạch)'!C32="","",'PV (Kế hoạch)'!C32) -> Không chèn thêm dòng vào dưới dòng này | AB32: =SUM(D32:AA32) -> 0
C33: TỔNG CỘNG TỪNG TUẦN | D33: =SUM(D3:D32) -> 4.94 | E33: =SUM(E3:E32) -> 5.07 | F33: =SUM(F3:F32) -> 5.99 | G33: =SUM(G3:G32) -> 8.95 | H33: =SUM(H3:H32) -> 11.14 | I33: =SUM(I3:I32) -> 9.91 | J33: =SUM(J3:J32) -> 9 | K33: =SUM(K3:K32) -> 10.04 | ... AB33: =SUM(AB3:AB32) -> 209.08
C34: TỔNG CỘNG LŨY KẾ | D34: =D33 -> 4.94 | E34: =D34+E33 -> 10.01 | F34: =E34+F33 -> 16 | G34: =F34+G33 -> 24.95 | H34: =G34+H33 -> 36.09 | I34: =H34+I33 -> 46 | J34: =I34+J33 -> 55 | K34: =J34+K33 -> 65.04 | L34: =K34+L33 -> 79.95 | ... AA34: =Z34+AA33 -> 209.08

Sheet AC (Chi phí thực tế)
B1: AC - ACTUAL COST (CHI PHÍ THỰC TẾ) (md)
B2: No. | C2: Hạng mục công việc | D2: Tuần 1 | E2: Tuần 2 | F2: Tuần 3 | G2: Tuần 4 | H2: Tuần 5 | I2: Tuần 6 | J2: Tuần 7 | K2: Tuần 8 | L2: Tuần 9 | M2: Tuần 10 | N2: Tuần 11 | O2: Tuần 12 | P2: Tuần 13 | Q2: Tuần 14 | R2: Tuần 15 | S2: Tuần 16 | T2: Tuần 17 | U2: Tuần 18 | V2: Tuần 19 | W2: Tuần 20 | X2: Tuần 21 | Y2: Tuần 22 | Z2: Tuần 23 | AA2: Tuần 24 | AB2: Tổng
B3: 1 | C3: Phân tích yêu cầu (Requirements Analysis) | D3: 5 | E3: 6 | F3: 4 | AB3: =SUM(D3:AA3) -> 15
B4: 2 | C4: Thiết kế hệ thống (System Design) | F4: 3 | G4: 6 | H4: 6 | I4: 3 | AB4: =SUM(D4:AA4) -> 18
B5: 3 | C5: Thiết kế database (Database Design) | G5: 3 | H5: 3 | I5: 4 | AB5: =SUM(D5:AA5) -> 10
B6: 4 | C6: Thiết kế UI/UX | G6: 2 | H6: 4 | I6: 4 | J6: 3 | AB6: =SUM(D6:AA6) -> 13
B7: 5 | C7: Phát triển Backend - Module User | I7: 2 | J7: 5 | K7: 6 | L7: 6 | M7: 4 | AB7: =SUM(D7:AA7) -> 23
B8: 6 | C8: Phát triển Backend - Module Order | K8: 2 | L8: 5 | M8: 6 | N8: 6 | O8: 4 | AB8: =SUM(D8:AA8) -> 23
B9: 7 | C9: Phát triển Backend - Module Payment | M9: 2 | N9: 5 | O9: 6 | P9: 6 | Q9: 2 | AB9: =SUM(D9:AA9) -> 21
B10: 8 | C10: Phát triển Backend - Module Report | O10: 2 | P10: 5 | Q10: 6 | R10: 4 | AB10: =SUM(D10:AA10) -> 17
B11: 9 | C11: Phát triển Frontend - Trang chủ | J11: 3 | K11: 3 | L11: 4 | AB11: =SUM(D11:AA11) -> 10
B12: 10 | C12: Phát triển Frontend - Module User | L12: 2 | M12: 5 | N12: 6 | O12: 4 | AB12: =SUM(D12:AA12) -> 17
B13: 11 | C13: Phát triển Frontend - Module Order | N13: 2 | O13: 5 | P13: 6 | Q13: 4 | AB13: =SUM(D13:AA13) -> 17
B14: 12 | C14: Phát triển Frontend - Module Payment | P14: 2 | Q14: 5 | R14: 6 | S14: 2 | AB14: =SUM(D14:AA14) -> 15
B15: 13 | C15: Phát triển Frontend - Module Report | R15: 2 | S15: 5 | T15: 4 | AB15: =SUM(D15:AA15) -> 11
B16: 14 | C16: Tích hợp API bên thứ 3 | AB16: =SUM(D16:AA16) -> 0
B17: 15 | C17: Unit Testing | AB17: =SUM(D17:AA17) -> 0
B18: 16 | C18: Integration Testing | AB18: =SUM(D18:AA18) -> 0
B19: 17 | C19: System Testing | AB19: =SUM(D19:AA19) -> 0
B20: 18 | C20: UAT (User Acceptance Testing) | AB20: =SUM(D20:AA20) -> 0
B21: 19 | C21: Bug fixing | AB21: =SUM(D21:AA21) -> 0
B22: 20 | C22: Performance Optimization | AB22: =SUM(D22:AA22) -> 0
B23: 21 | C23: Security Review | AB23: =SUM(D23:AA23) -> 0
B24: 22 | C24: Documentation | AB24: =SUM(D24:AA24) -> 0
B25: 23 | C25: Training | AB25: =SUM(D25:AA25) -> 0
B26: 24 | C26: Deployment | AB26: =SUM(D26:AA26) -> 0
B27: 25 | C27: Go-live Support | AB27: =SUM(D27:AA27) -> 0
B28: 26 | AB28: =SUM(D28:AA28) -> 0
B29: 27 | AB29: =SUM(D29:AA29) -> 0
B30: 28 | AB30: =SUM(D30:AA30) -> 0
B31: 29 | AB31: =SUM(D31:AA31) -> 0
B32: 30 | AB32: =SUM(D32:AA32) -> 0
C33: TỔNG CỘNG | D33: =SUM(D3:D32) -> 5 | E33: =SUM(E3:E32) -> 6 | F33: =SUM(F3:F32) -> 7 | G33: =SUM(G3:G32) -> 11 | H33: =SUM(H3:H32) -> 13 | I33: =SUM(I3:I32) -> 13 | J33: =SUM(J3:J32) -> 11 | K33: =SUM(K3:K32) -> 11 | ... AB33: =SUM(AB3:AB32) -> 210
C34: LŨY KẾ | D34: =D33 -> 5 | E34: =D34+E33 -> 11 | F34: =E34+F33 -> 18 | G34: =F34+G33 -> 29 | H34: =G34+H33 -> 42 | I34: =H34+I33 -> 55 | J34: =I34+J33 -> 66 | K34: =J34+K33 -> 77 | L34: =K34+L33 -> 94 | ... AA34: =Z34+AA33 -> 210

Sheet CPI (Chỉ số chi phí)
B1: CPI - COST PERFORMANCE INDEX (CHỈ SỐ HIỆU SUẤT CHI PHÍ)
B2: No. | C2: Hạng mục công việc | D2: Tuần 1 | E2: Tuần 2 | F2: Tuần 3 | G2: Tuần 4 | H2: Tuần 5 | I2: Tuần 6 | J2: Tuần 7 | K2: Tuần 8 | L2: Tuần 9 | M2: Tuần 10 | N2: Tuần 11 | O2: Tuần 12 | P2: Tuần 13 | Q2: Tuần 14 | R2: Tuần 15 | S2: Tuần 16 | T2: Tuần 17 | U2: Tuần 18 | V2: Tuần 19 | W2: Tuần 20 | X2: Tuần 21 | Y2: Tuần 22 | Z2: Tuần 23 | AA2: Tuần 24
B3: 1 | C3: ='PV (Kế hoạch)'!C3 -> Phân tích yêu cầu (Requirements Analysis) | D3: =IF('AC (Chi phí thực tế)'!D3=0,"",ROUND('EV (Hoàn thành thực tế)'!D3/'AC (Chi phí thực tế)'!D3,2)) -> 0.99 | E3: =IF('AC (Chi phí thực tế)'!E3=0,"",ROUND('EV (Hoàn thành thực tế)'!E3/'AC (Chi phí thực tế)'!E3,2)) -> 0.85 | F3: =IF('AC (Chi phí thực tế)'!F3=0,"",ROUND('EV (Hoàn thành thực tế)'!F3/'AC (Chi phí thực tế)'!F3,2)) -> 0.75 | G3: =IF('AC (Chi phí thực tế)'!G3=0,"",ROUND('EV (Hoàn thành thực tế)'!G3/'AC (Chi phí thực tế)'!G3,2)) | H3: =IF('AC (Chi phí thực tế)'!H3=0,"",ROUND('EV (Hoàn thành thực tế)'!H3/'AC (Chi phí thực tế)'!H3,2)) | I3: =IF('AC (Chi phí thực tế)'!I3=0,"",ROUND('EV (Hoàn thành thực tế)'!I3/'AC (Chi phí thực tế)'!I3,2)) | J3: =IF('AC (Chi phí thực tế)'!J3=0,"",ROUND('EV (Hoàn thành thực tế)'!J3/'AC (Chi phí thực tế)'!J3,2)) | K3: =IF('AC (Chi phí thực tế)'!K3=0,"",ROUND('EV (Hoàn thành thực tế)'!K3/'AC (Chi phí thực tế)'!K3,2)) | ... AA3: =IF('AC (Chi phí thực tế)'!AA3=0,"",ROUND('EV (Hoàn thành thực tế)'!AA3/'AC (Chi phí thực tế)'!AA3,2))
B4: 2 | C4: ='PV (Kế hoạch)'!C4 -> Thiết kế hệ thống (System Design) | D4: =IF('AC (Chi phí thực tế)'!D4=0,"",ROUND('EV (Hoàn thành thực tế)'!D4/'AC (Chi phí thực tế)'!D4,2)) | E4: =IF('AC (Chi phí thực tế)'!E4=0,"",ROUND('EV (Hoàn thành thực tế)'!E4/'AC (Chi phí thực tế)'!E4,2)) | F4: =IF('AC (Chi phí thực tế)'!F4=0,"",ROUND('EV (Hoàn thành thực tế)'!F4/'AC (Chi phí thực tế)'!F4,2)) -> 1 | G4: =IF('AC (Chi phí thực tế)'!G4=0,"",ROUND('EV (Hoàn thành thực tế)'!G4/'AC (Chi phí thực tế)'!G4,2)) -> 0.83 | H4: =IF('AC (Chi phí thực tế)'!H4=0,"",ROUND('EV (Hoàn thành thực tế)'!H4/'AC (Chi phí thực tế)'!H4,2)) -> 0.85 | I4: =IF('AC (Chi phí thực tế)'!I4=0,"",ROUND('EV (Hoàn thành thực tế)'!I4/'AC (Chi phí thực tế)'!I4,2)) -> 0.65 | J4: =IF('AC (Chi phí thực tế)'!J4=0,"",ROUND('EV (Hoàn thành thực tế)'!J4/'AC (Chi phí thực tế)'!J4,2)) | K4: =IF('AC (Chi phí thực tế)'!K4=0,"",ROUND('EV (Hoàn thành thực tế)'!K4/'AC (Chi phí thực tế)'!K4,2)) | ... AA4: =IF('AC (Chi phí thực tế)'!AA4=0,"",ROUND('EV (Hoàn thành thực tế)'!AA4/'AC (Chi phí thực tế)'!AA4,2))
B5: 3 | C5: ='PV (Kế hoạch)'!C5 -> Thiết kế database (Database Design) | D5: =IF('AC (Chi phí thực tế)'!D5=0,"",ROUND('EV (Hoàn thành thực tế)'!D5/'AC (Chi phí thực tế)'!D5,2)) | E5: =IF('AC (Chi phí thực tế)'!E5=0,"",ROUND('EV (Hoàn thành thực tế)'!E5/'AC (Chi phí thực tế)'!E5,2)) | F5: =IF('AC (Chi phí thực tế)'!F5=0,"",ROUND('EV (Hoàn thành thực tế)'!F5/'AC (Chi phí thực tế)'!F5,2)) | G5: =IF('AC (Chi phí thực tế)'!G5=0,"",ROUND('EV (Hoàn thành thực tế)'!G5/'AC (Chi phí thực tế)'!G5,2)) -> 0.67 | H5: =IF('AC (Chi phí thực tế)'!H5=0,"",ROUND('EV (Hoàn thành thực tế)'!H5/'AC (Chi phí thực tế)'!H5,2)) -> 1.01 | I5: =IF('AC (Chi phí thực tế)'!I5=0,"",ROUND('EV (Hoàn thành thực tế)'!I5/'AC (Chi phí thực tế)'!I5,2)) -> 0.74 | J5: =IF('AC (Chi phí thực tế)'!J5=0,"",ROUND('EV (Hoàn thành thực tế)'!J5/'AC (Chi phí thực tế)'!J5,2)) | K5: =IF('AC (Chi phí thực tế)'!K5=0,"",ROUND('EV (Hoàn thành thực tế)'!K5/'AC (Chi phí thực tế)'!K5,2)) | ... AA5: =IF('AC (Chi phí thực tế)'!AA5=0,"",ROUND('EV (Hoàn thành thực tế)'!AA5/'AC (Chi phí thực tế)'!AA5,2))
B6: 4 | C6: ='PV (Kế hoạch)'!C6 -> Thiết kế UI/UX | D6: =IF('AC (Chi phí thực tế)'!D6=0,"",ROUND('EV (Hoàn thành thực tế)'!D6/'AC (Chi phí thực tế)'!D6,2)) | E6: =IF('AC (Chi phí thực tế)'!E6=0,"",ROUND('EV (Hoàn thành thực tế)'!E6/'AC (Chi phí thực tế)'!E6,2)) | F6: =IF('AC (Chi phí thực tế)'!F6=0,"",ROUND('EV (Hoàn thành thực tế)'!F6/'AC (Chi phí thực tế)'!F6,2)) | G6: =IF('AC (Chi phí thực tế)'!G6=0,"",ROUND('EV (Hoàn thành thực tế)'!G6/'AC (Chi phí thực tế)'!G6,2)) -> 1 | H6: =IF('AC (Chi phí thực tế)'!H6=0,"",ROUND('EV (Hoàn thành thực tế)'!H6/'AC (Chi phí thực tế)'!H6,2)) -> 0.75 | I6: =IF('AC (Chi phí thực tế)'!I6=0,"",ROUND('EV (Hoàn thành thực tế)'!I6/'AC (Chi phí thực tế)'!I6,2)) -> 0.75 | J6: =IF('AC (Chi phí thực tế)'!J6=0,"",ROUND('EV (Hoàn thành thực tế)'!J6/'AC (Chi phí thực tế)'!J6,2)) -> 0.67 | K6: =IF('AC (Chi phí thực tế)'!K6=0,"",ROUND('EV (Hoàn thành thực tế)'!K6/'AC (Chi phí thực tế)'!K6,2)) | ... AA6: =IF('AC (Chi phí thực tế)'!AA6=0,"",ROUND('EV (Hoàn thành thực tế)'!AA6/'AC (Chi phí thực tế)'!AA6,2))
B7: 5 | C7: ='PV (Kế hoạch)'!C7 -> Phát triển Backend - Module User | D7: =IF('AC (Chi phí thực tế)'!D7=0,"",ROUND('EV (Hoàn thành thực tế)'!D7/'AC (Chi phí thực tế)'!D7,2)) | E7: =IF('AC (Chi phí thực tế)'!E7=0,"",ROUND('EV (Hoàn thành thực tế)'!E7/'AC (Chi phí thực tế)'!E7,2)) | F7: =IF('AC (Chi phí thực tế)'!F7=0,"",ROUND('EV (Hoàn thành thực tế)'!F7/'AC (Chi phí thực tế)'!F7,2)) | G7: =IF('AC (Chi phí thực tế)'!G7=0,"",ROUND('EV (Hoàn thành thực tế)'!G7/'AC (Chi phí thực tế)'!G7,2)) | H7: =IF('AC (Chi phí thực tế)'!H7=0,"",ROUND('EV (Hoàn thành thực tế)'!H7/'AC (Chi phí thực tế)'!H7,2)) | I7: =IF('AC (Chi phí thực tế)'!I7=0,"",ROUND('EV (Hoàn thành thực tế)'!I7/'AC (Chi phí thực tế)'!I7,2)) -> 1 | J7: =IF('AC (Chi phí thực tế)'!J7=0,"",ROUND('EV (Hoàn thành thực tế)'!J7/'AC (Chi phí thực tế)'!J7,2)) -> 1 | K7: =IF('AC (Chi phí thực tế)'!K7=0,"",ROUND('EV (Hoàn thành thực tế)'!K7/'AC (Chi phí thực tế)'!K7,2)) -> 0.83 | ... AA7: =IF('AC (Chi phí thực tế)'!AA7=0,"",ROUND('EV (Hoàn thành thực tế)'!AA7/'AC (Chi phí thực tế)'!AA7,2))
B8: 6 | C8: ='PV (Kế hoạch)'!C8 -> Phát triển Backend - Module Order | D8: =IF('AC (Chi phí thực tế)'!D8=0,"",ROUND('EV (Hoàn thành thực tế)'!D8/'AC (Chi phí thực tế)'!D8,2)) | E8: =IF('AC (Chi phí thực tế)'!E8=0,"",ROUND('EV (Hoàn thành thực tế)'!E8/'AC (Chi phí thực tế)'!E8,2)) | F8: =IF('AC (Chi phí thực tế)'!F8=0,"",ROUND('EV (Hoàn thành thực tế)'!F8/'AC (Chi phí thực tế)'!F8,2)) | G8: =IF('AC (Chi phí thực tế)'!G8=0,"",ROUND('EV (Hoàn thành thực tế)'!G8/'AC (Chi phí thực tế)'!G8,2)) | H8: =IF('AC (Chi phí thực tế)'!H8=0,"",ROUND('EV (Hoàn thành thực tế)'!H8/'AC (Chi phí thực tế)'!H8,2)) | I8: =IF('AC (Chi phí thực tế)'!I8=0,"",ROUND('EV (Hoàn thành thực tế)'!I8/'AC (Chi phí thực tế)'!I8,2)) | J8: =IF('AC (Chi phí thực tế)'!J8=0,"",ROUND('EV (Hoàn thành thực tế)'!J8/'AC (Chi phí thực tế)'!J8,2)) | K8: =IF('AC (Chi phí thực tế)'!K8=0,"",ROUND('EV (Hoàn thành thực tế)'!K8/'AC (Chi phí thực tế)'!K8,2)) -> 1 | ... AA8: =IF('AC (Chi phí thực tế)'!AA8=0,"",ROUND('EV (Hoàn thành thực tế)'!AA8/'AC (Chi phí thực tế)'!AA8,2))
B9: 7 | C9: ='PV (Kế hoạch)'!C9 -> Phát triển Backend - Module Payment | D9: =IF('AC (Chi phí thực tế)'!D9=0,"",ROUND('EV (Hoàn thành thực tế)'!D9/'AC (Chi phí thực tế)'!D9,2)) | E9: =IF('AC (Chi phí thực tế)'!E9=0,"",ROUND('EV (Hoàn thành thực tế)'!E9/'AC (Chi phí thực tế)'!E9,2)) | F9: =IF('AC (Chi phí thực tế)'!F9=0,"",ROUND('EV (Hoàn thành thực tế)'!F9/'AC (Chi phí thực tế)'!F9,2)) | G9: =IF('AC (Chi phí thực tế)'!G9=0,"",ROUND('EV (Hoàn thành thực tế)'!G9/'AC (Chi phí thực tế)'!G9,2)) | H9: =IF('AC (Chi phí thực tế)'!H9=0,"",ROUND('EV (Hoàn thành thực tế)'!H9/'AC (Chi phí thực tế)'!H9,2)) | I9: =IF('AC (Chi phí thực tế)'!I9=0,"",ROUND('EV (Hoàn thành thực tế)'!I9/'AC (Chi phí thực tế)'!I9,2)) | J9: =IF('AC (Chi phí thực tế)'!J9=0,"",ROUND('EV (Hoàn thành thực tế)'!J9/'AC (Chi phí thực tế)'!J9,2)) | K9: =IF('AC (Chi phí thực tế)'!K9=0,"",ROUND('EV (Hoàn thành thực tế)'!K9/'AC (Chi phí thực tế)'!K9,2)) | ... AA9: =IF('AC (Chi phí thực tế)'!AA9=0,"",ROUND('EV (Hoàn thành thực tế)'!AA9/'AC (Chi phí thực tế)'!AA9,2))
